Workbook

Sheet Input
A1: DataSet/Point | B1: 1 / 1 . | C1: 4 / 1 . | D1: 5 / 1 . | E1: 6 / 1 . | F1: 17 / 1 . | G1: 18 / 1 . | H1: 19 / 1 . | I1: 20 / 1 . | J1: 26 / 1 . | K1: 27 / 1 . | L1: 28 / 1 . | M1: 33 / 1 . | N1: 34 / 1 . | O1: 35 / 1 . | P1: 43 / 1 . | Q1: 44 / 1 . | R1: 50 / 1 . | S1: 51 / 1 . | T1: 52 / 1 . | U1: 55 / 1 . | V1: 56 / 1 . | W1: 58 / 1 . | X1: 59 / 1 . | Y1: 60 / 1 . | Z1: 61 / 1 . | AA1: 64 / 1 . | AB1: 65 / 1 . | AC1: 69 / 1 . | AD1: 70 / 1 . | AE1: 72 / 1 . | AF1: 73 / 1 . | AG1: 75 / 1 . | AH1: 76 / 1 . | AI1: 77 / 1 . | AJ1: 78 / 1 . | AK1: 79 / 1 . | AL1: 82 / 1 . | AM1: 83 / 1 . | AN1: 84 / 1 . | AO1: 85 / 1 . | AP1: 86 / 1 . | AQ1: 87 / 1 . | AR1: 89 / 1 . | AS1: 90 / 1 . | AT1: 91 / 1 . | AU1: 92 / 1 . | AV1: 94 / 1 . | AW1: 95 / 1 . | AX1: 97 / 1 . | AY1: 98 / 1 . | AZ1: 99 / 1 . | BA1: 101 / 1 . | BB1: 102 / 1 . | BC1: 108 / 1 . | BD1: 109 / 1 . | BE1: 110 / 1 . | BF1: 111 / 1 . | BG1: 114 / 1 . | BH1: 115 / 1 . | BI1: 117 / 1 . | BJ1: 118 / 1 .
A2: Comment | B2: YG182_test amph | C2: YG182_1_AmphC | D2: YG182_1_AmphB | E2: YG182_1_AmphB | F2: YG182_2_AmphC | G2: YG182_2_AmphB | H2: YG182_2_AmphC | I2: YG182_2_AmphB | J2: YG182_3_AmphC | K2: YG182_3_AmphB | L2: YG182_3_AmphB | M2: YG182_4_AmpC | N2: YG182_4_AmpC | O2: YG182_4_AmpB | P2: 19NC11C_1_AmphC | Q2: 19NC11C_1_AmphB | R2: 19NC11C_2_AmphC | S2: 19NC11C_2_AmphB | T2: 19NC11C_2_AmphB | U2: 19NC11C_2_AmpB | V2: 19NC11C_2_AmpC | W2: 19NC11C_3_AmphC | X2: 19NC11C_3_AmphB | Y2: 19NC11C_4_AmphC | Z2: 19NC11C_4_AmphB | AA2: SL59_1_AmphC | AB2: SL59_1_AmphB | AC2: SL59_2_AmphC | AD2: SL59_2_AmphB | AE2: SL59_3_AmphC | AF2: SL59_3_AmphB | AG2: SL59_4_AmphC | AH2: SL59_4_AmphB | AI2: SL59_4_AmphC | AJ2: SL59_4_AmphB | AK2: 19NC6D_4_AmphC | AL2: 19NC6D_4_AmphC | AM2: 19NC6D_3_AmphC | AN2: 19NC6D_3_AmphB | AO2: 19NC6D_3_AmphC | AP2: YG41_1_AmphC | AQ2: YG41_1_AmphB | AR2: YG41_1_AmphC | AS2: YG41_1_AmphB | AT2: YG41_1_AmphC | AU2: YG41_1_AmphB | AV2: YG41_2_AmphC | AW2: YG41_3_AmphB | AX2: YG41_4_AmphC | AY2: YG41_4_AmphC | AZ2: YG41_4_AmphB | BA2: 19NC04_X_AmphC | BB2: 19NC04_X_AmphB | BC2: 19NC04_X_Amph | BD2: 19NC04_X_Amph | BE2: 19NC04_X_Amph | BF2: 19NC08B_1_Amph | BG2: 19NC08B_X_AmphC | BH2: 19NC08B_X_AmphB | BI2: 19NC08B_X_Amph | BJ2: 19NC08B_X_AmphB
A3: SiO2 | B3: 46.44 | C3: 45.22 | D3: 44.98 | E3: 44.03 | F3: 44.95 | G3: 44.23 | H3: 44.96 | I3: 45.33 | J3: 45.95 | K3: 44.19 | L3: 45.63 | M3: 44.73 | N3: 45.72 | O3: 44.31 | P3: 44.7 | Q3: 51.09 | R3: 42.91 | S3: 42.89 | T3: 42.61 | U3: 42.07 | V3: 42.23 | W3: 45.55 | X3: 44.27 | Y3: 41.03 | Z3: 44.42 | AA3: 46.99 | AB3: 44.27 | AC3: 43.54 | AD3: 42.81 | AE3: 42.5 | AF3: 43.06 | AG3: 42.37 | AH3: 43.38 | AI3: 42.26 | AJ3: 43.27 | AK3: 43.92 | AL3: 43.51 | AM3: 44.27 | AN3: 44.19 | AO3: 44.27 | AP3: 44.29 | AQ3: 44.56 | AR3: 44.18 | AS3: 44.01 | AT3: 43.91 | AU3: 45.76 | AV3: 43.95 | AW3: 42.92 | AX3: 43.27 | AY3: 43.81 | AZ3: 44.32 | BA3: 43.24 | BB3: 43.13 | BC3: 42.3 | BD3: 42.86 | BE3: 42.82 | BF3: 41.75 | BG3: 41.26 | BH3: 42.62 | BI3: 41.5 | BJ3: 41.82
A4: TiO2 | B4: 0.44 | C4: 0.55 | D4: 0.57 | E4: 0.39 | F4: 0.62 | G4: 0.58 | H4: 0.6 | I4: 0.61 | J4: 0.49 | K4: 0.44 | L4: 0.6 | M4: 0.63 | N4: 0.63 | O4: 0.79 | P4: 1.37 | Q4: 0.08 | R4: 1.63 | S4: 1.59 | T4: 1.59 | U4: 1.55 | V4: 1.49 | W4: 0.85 | X4: 0.86 | Y4: 1.24 | Z4: 0.63 | AA4: 0.92 | AB4: 2.24 | AC4: 2.48 | AD4: 2.52 | AE4: 2.53 | AF4: 2.5 | AG4: 2.63 | AH4: 2.34 | AI4: 2.63 | AJ4: 2.36 | AK4: 0.77 | AL4: 0.9 | AM4: 0.78 | AN4: 0.72 | AO4: 0.78 | AP4: 0.87 | AQ4: 0.95 | AR4: 0.88 | AS4: 0.97 | AT4: 0.93 | AU4: 0.6 | AV4: 1.05 | AW4: 0.8 | AX4: 0.76 | AY4: 1.04 | AZ4: 0.92 | BA4: 1.49 | BB4: 1.51 | BC4: 1.44 | BD4: 1.38 | BE4: 1.56 | BF4: 1.82 | BG4: 1.87 | BH4: 1.57 | BI4: 1.98 | BJ4: 1.94
A5: Cr2O3 | B5: 0.05 | C5: 0.04 | D5: 0.03 | E5: 0.05 | F5: 0.03 | G5: 0.02 | H5: 0.07 | I5: 0.05 | J5: 0.06 | K5: 0.01 | L5: 0.05 | M5: 0.04 | N5: 0.06 | O5: 0.04 | P5: 0.09 | Q5: 0.02 | R5: 0.11 | S5: 0.11 | T5: 0.1 | U5: 0.11 | V5: 0.1 | W5: 0.07 | X5: 0.07 | Y5: 0.17 | Z5: 0.09 | AA5: 0.09 | AB5: 0.11 | AC5: 0.25 | AD5: 0.23 | AE5: 0.11 | AF5: 0.15 | AG5: 0.06 | AH5: 0.02 | AI5: 0.05 | AJ5: 0.04 | AK5: 0.02 | AL5: 0.02 | AM5: 0.06 | AN5: 0.07 | AO5: 0.07 | AP5: 0.05 | AQ5: 0.05 | AR5: 0.03 | AS5: 0.03 | AT5: 0.02 | AU5: 0.03 | AV5: 0.02 | AW5: 0 | AX5: 0.03 | AY5: 0.05 | AZ5: 0.02 | BA5: 0.02 | BB5: 0.02 | BC5: 0.03 | BD5: 0.02 | BE5: 0.01 | BF5: 0.03 | BG5: 0 | BH5: 0.03 | BI5: 0.02 | BJ5: 0.01
A6: Al2O3 | B6: 9.56 | C6: 11.21 | D6: 11.78 | E6: 11.73 | F6: 11.48 | G6: 11.91 | H6: 11.54 | I6: 11.44 | J6: 10.87 | K6: 9.27 | L6: 11.37 | M6: 11.74 | N6: 11.6 | O6: 12.23 | P6: 9.49 | Q6: 4.81 | R6: 11.31 | S6: 11.45 | T6: 11.29 | U6: 11.81 | V6: 11.96 | W6: 8.35 | X6: 10.17 | Y6: 15.09 | Z6: 11.22 | AA6: 9.44 | AB6: 11.11 | AC6: 12.36 | AD6: 12.32 | AE6: 12.53 | AF6: 11.91 | AG6: 12.98 | AH6: 12.96 | AI6: 12.61 | AJ6: 12.26 | AK6: 12.93 | AL6: 13.26 | AM6: 12.94 | AN6: 12.75 | AO6: 12.69 | AP6: 10.06 | AQ6: 10.34 | AR6: 10.36 | AS6: 10.38 | AT6: 10.18 | AU6: 8.58 | AV6: 10.35 | AW6: 10.96 | AX6: 11.96 | AY6: 10.31 | AZ6: 10.25 | BA6: 11.51 | BB6: 11.74 | BC6: 11.15 | BD6: 11.97 | BE6: 11.79 | BF6: 12.13 | BG6: 12.22 | BH6: 11.66 | BI6: 12.08 | BJ6: 11.73
A7: FeO | B7: 13.78 | C7: 13.44 | D7: 14.5 | E7: 14.61 | F7: 13.9 | G7: 14.65 | H7: 13.48 | I7: 14.11 | J7: 13.8 | K7: 14.59 | L7: 13.72 | M7: 13.89 | N7: 13.89 | O7: 14.45 | P7: 13.43 | Q7: 10.05 | R7: 14.33 | S7: 14.27 | T7: 14.68 | U7: 14.78 | V7: 14.53 | W7: 14.42 | X7: 14.05 | Y7: 13.83 | Z7: 13.77 | AA7: 11.56 | AB7: 13.27 | AC7: 12.17 | AD7: 12.75 | AE7: 13.48 | AF7: 13.12 | AG7: 13.32 | AH7: 13.09 | AI7: 12.99 | AJ7: 12.81 | AK7: 13.82 | AL7: 13.7 | AM7: 13.66 | AN7: 13.61 | AO7: 13.31 | AP7: 18.22 | AQ7: 17.73 | AR7: 17.92 | AS7: 18.48 | AT7: 18.3 | AU7: 17.48 | AV7: 18.6 | AW7: 18.39 | AX7: 15.96 | AY7: 18.37 | AZ7: 17.99 | BA7: 14.83 | BB7: 14.88 | BC7: 14.95 | BD7: 14.98 | BE7: 15.18 | BF7: 17 | BG7: 17.29 | BH7: 16.65 | BI7: 17.2 | BJ7: 16.39
A8: MnO | B8: 0.68 | C8: 0.84 | D8: 1.01 | E8: 1.11 | F8: 0.85 | G8: 0.84 | H8: 0.81 | I8: 0.85 | J8: 0.89 | K8: 0.89 | L8: 0.9 | M8: 0.77 | N8: 0.69 | O8: 0.7 | P8: 0.22 | Q8: 0.23 | R8: 0.18 | S8: 0.2 | T8: 0.21 | U8: 0.19 | V8: 0.26 | W8: 0.25 | X8: 0.23 | Y8: 0.15 | Z8: 0.21 | AA8: 0.18 | AB8: 0.26 | AC8: 0.14 | AD8: 0.21 | AE8: 0.24 | AF8: 0.22 | AG8: 0.24 | AH8: 0.21 | AI8: 0.25 | AJ8: 0.24 | AK8: 0.25 | AL8: 0.2 | AM8: 0.18 | AN8: 0.21 | AO8: 0.28 | AP8: 0.31 | AQ8: 0.27 | AR8: 0.34 | AS8: 0.34 | AT8: 0.33 | AU8: 0.27 | AV8: 0.28 | AW8: 0.26 | AX8: 0.25 | AY8: 0.3 | AZ8: 0.3 | BA8: 0.2 | BB8: 0.24 | BC8: 0.18 | BD8: 0.2 | BE8: 0.18 | BF8: 0.16 | BG8: 0.25 | BH8: 0.2 | BI8: 0.21 | BJ8: 0.24
A9: NiO | B9: 0.03 | C9: 0 | D9: 0 | E9: 0.03
A10: MgO | B10: 12.46 | C10: 13 | D10: 12.06 | E10: 11.98 | F10: 12.24 | G10: 11.92 | H10: 12.39 | I10: 12.42 | J10: 12.84 | K10: 11.1 | L10: 12.84 | M10: 12.18 | N10: 11.8 | O10: 12.09 | P10: 12.36 | Q10: 16.41 | R10: 11.66 | S10: 11.64 | T10: 11.74 | U10: 11.16 | V10: 11.2 | W10: 12.17 | X10: 12.38 | Y10: 7.05 | Z10: 11.19 | AA10: 12.51 | AB10: 12.98 | AC10: 12.59 | AD10: 12.28 | AE10: 12.11 | AF10: 12.34 | AG10: 11.88 | AH10: 12.38 | AI10: 11.88 | AJ10: 12.43 | AK10: 11.29 | AL10: 11.1 | AM10: 11.65 | AN10: 11.48 | AO10: 11.58 | AP10: 9.88 | AQ10: 9.89 | AR10: 9.8 | AS10: 9.65 | AT10: 9.62 | AU10: 10.79 | AV10: 9.58 | AW10: 9.42 | AX10: 7.53 | AY10: 9.46 | AZ10: 9.92 | BA10: 11.34 | BB10: 11.19 | BC10: 11.34 | BD10: 11.05 | BE10: 11.48 | BF10: 9.52 | BG10: 9.45 | BH10: 9.83 | BI10: 9.33 | BJ10: 9.73
A11: CaO | B11: 10.49 | C11: 10.53 | D11: 10.55 | E11: 10 | F11: 10.87 | G11: 10.94 | H11: 11.02 | I11: 10.81 | J11: 10.26 | K11: 10.35 | L11: 10.48 | M11: 10.81 | N11: 10.39 | O11: 10.85 | P11: 12.13 | Q11: 12.64 | R11: 11.95 | S11: 12.03 | T11: 12.07 | U11: 11.87 | V11: 12.09 | W11: 12.05 | X11: 11.83 | Y11: 16.24 | Z11: 13.1 | AA11: 13.58 | AB11: 11.34 | AC11: 11.29 | AD11: 11.48 | AE11: 11.12 | AF11: 11.2 | AG11: 11.21 | AH11: 11.17 | AI11: 11.24 | AJ11: 11.01 | AK11: 11.05 | AL11: 10.92 | AM11: 10.87 | AN11: 10.71 | AO11: 10.88 | AP11: 11.79 | AQ11: 11.69 | AR11: 11.85 | AS11: 11.78 | AT11: 11.42 | AU11: 11.74 | AV11: 11.44 | AW11: 11.67 | AX11: 14.35 | AY11: 11.48 | AZ11: 11.74 | BA11: 12.02 | BB11: 11.82 | BC11: 11.92 | BD11: 11.95 | BE11: 12 | BF11: 11.59 | BG11: 11.34 | BH11: 11.69 | BI11: 11.4 | BJ11: 11.98
A12: Na2O | B12: 1.35 | C12: 1.4 | D12: 1.51 | E12: 1.39 | F12: 1.39 | G12: 1.47 | H12: 1.37 | I12: 1.41 | J12: 1.41 | K12: 1.29 | L12: 1.53 | M12: 1.45 | N12: 1.63 | O12: 1.51 | P12: 1.38 | Q12: 0.74 | R12: 1.67 | S12: 1.57 | T12: 1.6 | U12: 1.64 | V12: 1.68 | W12: 1.24 | X12: 1.52 | Y12: 1.05 | Z12: 1.26 | AA12: 1.17 | AB12: 2.08 | AC12: 2.47 | AD12: 2.51 | AE12: 2.58 | AF12: 2.63 | AG12: 2.64 | AH12: 2.59 | AI12: 2.55 | AJ12: 2.56 | AK12: 2.44 | AL12: 2.59 | AM12: 2.47 | AN12: 2.49 | AO12: 2.58 | AP12: 1.41 | AQ12: 1.3 | AR12: 1.44 | AS12: 1.49 | AT12: 1.58 | AU12: 1.16 | AV12: 1.54 | AW12: 1.53 | AX12: 1 | AY12: 1.59 | AZ12: 1.44 | BA12: 1.97 | BB12: 1.99 | BC12: 1.91 | BD12: 1.95 | BE12: 1.96 | BF12: 2.38 | BG12: 2.42 | BH12: 2.25 | BI12: 2.22 | BJ12: 2.18
A13: K2O | B13: 0.24 | C13: 0.14 | D13: 0.27 | E13: 0.25 | F13: 0.34 | G13: 0.26 | H13: 0.21 | I13: 0.23 | J13: 0.16 | K13: 0.27 | L13: 0.14 | M13: 0.22 | N13: 0.25 | O13: 0.25 | P13: 0.73 | Q13: 0.26 | R13: 0.99 | S13: 1.02 | T13: 0.94 | U13: 1.01 | V13: 1.07 | W13: 0.7 | X13: 0.76 | Y13: 0.67 | Z13: 0.69 | AA13: 0.04 | AB13: 0.1 | AC13: 0.15 | AD13: 0.14 | AE13: 0.14 | AF13: 0.12 | AG13: 0.14 | AH13: 0.12 | AI13: 0.18 | AJ13: 0.12 | AK13: 0.45 | AL13: 0.32 | AM13: 0.38 | AN13: 0.37 | AO13: 0.28 | AP13: 0.13 | AQ13: 0.18 | AR13: 0.15 | AS13: 0.16 | AT13: 0.04 | AU13: 0.16 | AV13: 0.14 | AW13: 0.17 | AX13: 0.07 | AY13: 0.08 | AZ13: 0.17 | BA13: 0.04 | BB13: 0.03 | BC13: 0.04 | BD13: 0.07 | BE13: 0.09 | BF13: 0.09 | BG13: 0.14 | BH13: 0.08 | BI13: 0.05 | BJ13: 0.12
A14: H2O
A15: F
A16: Cl
A17: Total | B17: 95.54 | C17: 96.37 | D17: 97.28 | E17: 95.64 | F17: 96.68 | G17: 96.81 | H17: 96.46 | I17: 97.25 | J17: 96.75 | K17: 92.4 | L17: 97.25 | M17: 96.46 | N17: 96.66 | O17: 97.22 | P17: 95.89 | Q17: 96.33 | R17: 96.74 | S17: 96.77 | T17: 96.81 | U17: 96.2 | V17: 96.61 | W17: 95.65 | X17: 96.13 | Y17: 96.52 | Z17: 96.56 | AA17: 96.47 | AB17: 97.76 | AC17: 97.44 | AD17: 97.25 | AE17: 97.34 | AF17: 97.25 | AG17: 97.48 | AH17: 98.25 | AI17: 96.64 | AJ17: 97.1 | AK17: 96.95 | AL17: 96.52 | AM17: 97.26 | AN17: 96.6 | AO17: 96.72 | AP17: 97.01 | AQ17: 96.95 | AR17: 96.96 | AS17: 97.28 | AT17: 96.33 | AU17: 96.56 | AV17: 96.93 | AW17: 96.12 | AX17: 95.18 | AY17: 96.48 | AZ17: 97.07 | BA17: 96.66 | BB17: 96.57 | BC17: 95.27 | BD17: 96.43 | BE17: 97.07 | BF17: 96.48 | BG17: 96.24 | BH17: 96.59 | BI17: 96 | BJ17: 96.13
A20: Xfe3 for RAMP | B20: 0.2 | D20: F3+/Fetot
A24: DataSet/Point | B24: 1 / 1 . | C24: 10 / 1 . | D24: 17 / 1 . | E24: 22 / 1 . | F24: 26 / 1 . | G24: 28 / 1 . | H24: 29 / 1 . | I24: 30 / 1 . | J24: 31 / 1 . | K24: 34 / 1 . | L24: 35 / 1 . | M24: 36 / 1 . | N24: 37 / 1 . | O24: 41 / 1 . | P24: 42 / 1 . | Q24: 43 / 1 . | R24: 44 / 1 . | S24: 49 / 1 . | T24: 55 / 1 . | U24: 1 / 1 . | V24: 2 / 1 . | W24: 3 / 1 . | X24: 9 / 1 . | Y24: 10 / 1 . | Z24: 15 / 1 . | AA24: 16 / 1 . | AB24: 17 / 1 . | AC24: 25 / 1 . | AD24: 26 / 1 . | AE24: 29 / 1 . | AF24: 38 / 1 . | AG24: 41 / 1 . | AH24: 42 / 1 . | AI24: 46 / 1 . | AJ24: 47 / 1 . | AK24: 51 / 1 . | AL24: 57 / 1 .
A25: Al2O3 | B25: 3.3311 | C25: 0.8712 | D25: 1.7159 | E25: 26.203 | F25: 2.3119 | G25: 0.8069 | H25: 0.2297 | I25: 0.5896 | J25: 0.5228 | K25: 0.7624 | L25: 0.3529 | M25: 0.4715 | N25: 0.5386 | O25: 0.5158 | P25: 0.2355 | Q25: 0.9828 | R25: 0.1275 | S25: 0.7518 | T25: 1.1211 | U25: 0.2218 | V25: 0.1269 | W25: 0.5443 | X25: 0.3802 | Y25: 0.7515 | Z25: 0.0084 | AA25: 0.0194 | AB25: 0.0079 | AC25: 0.6533 | AD25: 1.4126 | AE25: 2.7088 | AF25: 0.691 | AG25: 1.0819 | AH25: 1.2539 | AI25: 1.2638 | AJ25: 1.1834 | AK25: 0.9422 | AL25: 1.1647
A26: SiO2 | B26: 56.0855 | C26: 46.8614 | D26: 57.087 | E26: 39.288 | F26: 54.7456 | G26: 56.8081 | H26: 56.9725 | I26: 56.8367 | J26: 56.5803 | K26: 56.8423 | L26: 57.3053 | M26: 57.1437 | N26: 56.8251 | O26: 57.2987 | P26: 57.3679 | Q26: 55.8048 | R26: 57.4408 | S26: 56.9793 | T26: 56.9206 | U26: 57.6755 | V26: 57.4831 | W26: 56.9842 | X26: 57.3848 | Y26: 57.3404 | Z26: 57.5181 | AA26: 57.8094 | AB26: 58.104 | AC26: 57.1233 | AD26: 57.0057 | AE26: 56.6083 | AF26: 56.9081 | AG26: 56.3142 | AH26: 56.6015 | AI26: 56.5624 | AJ26: 56.4456 | AK26: 56.662 | AL26: 56.8947
A27: TiO2 | B27: 0.0313 | C27: 0.0083 | D27: -0.0057 | E27: 0.062 | F27: 0.3075 | G27: 0.0077 | H27: 0 | I27: -0.0062 | J27: 0 | K27: 0.0046 | L27: 0.0108 | M27: 0.0222 | N27: 0.0268 | O27: -0.0046 | P27: -0.0052 | Q27: 0.0201 | R27: 0.0273 | S27: 0.0182 | T27: 0.0124 | U27: 0.0704 | V27: 0.002 | W27: 0.0072 | X27: 0.0067 | Y27: 0.0118 | Z27: 0.0038 | AA27: -0.0173 | AB27: -0.0239 | AC27: 0.0038 | AD27: -0.0156 | AE27: -0.0027 | AF27: 0 | AG27: 0.0027 | AH27: 0.0107 | AI27: 0.0043 | AJ27: 0.0113 | AK27: 0.0118 | AL27: -0.0113
A28: Cr2O3 | B28: 0.2769 | C28: 0.055 | D28: 0.0015 | E28: 0.0209 | F28: 0.4806 | G28: 0.1632 | H28: 0.0754 | I28: -0.0058 | J28: -0.0068 | K28: 0.0161 | L28: 0.0108 | M28: 0.001 | N28: 0.0259 | O28: 0.001 | P28: 0.0049 | Q28: -0.0024 | R28: 0.0294 | S28: 0.04 | T28: 0.073 | U28: 0.0219 | V28: -0.0053 | W28: 0.001 | X28: 0.0102 | Y28: 0.0223 | Z28: -0.0036 | AA28: 0.0258 | AB28: -0.0227 | AC28: 0.0195 | AD28: 0.0056 | AE28: 0.0459 | AF28: 0.022 | AG28: 0.1457 | AH28: 0.0728 | AI28: 0.0122 | AJ28: 0.0061 | AK28: 0.0066 | AL28: 0.0255
A29: Na2O | B29: 1.2956 | C29: 0.5731 | D29: 1.1869 | E29: 0.1999 | F29: 0.7042 | G29: 0.7007 | H29: 0.3806 | I29: 0.8147 | J29: 0.6513 | K29: 0.668 | L29: 0.458 | M29: 0.4815 | N29: 0.6184 | O29: 0.5539 | P29: 0.3691 | Q29: 0.3251 | R29: 0.2103 | S29: 0.2564 | T29: 0.8121 | U29: 0.0969 | V29: 0.175 | W29: 0.2634 | X29: 0.2262 | Y29: 0.333 | Z29: 0.0769 | AA29: 0.0666 | AB29: 0.101 | AC29: 0.3082 | AD29: 0.5746 | AE29: 0.4438 | AF29: 0.5932 | AG29: 0.5735 | AH29: 0.6181 | AI29: 0.6618 | AJ29: 0.6488 | AK29: 0.6447 | AL29: 0.6276
A30: MgO | B30: 18.9947 | C30: 17.5677 | D30: 20.6019 | E30: 4.1393 | F30: 19.9949 | G30: 20.305 | H30: 21.3774 | I30: 20.4156 | J30: 20.6378 | K30: 20.657 | L30: 20.9385 | M30: 20.8152 | N30: 20.8007 | O30: 20.6931 | P30: 20.9955 | Q30: 21.5068 | R30: 21.4656 | S30: 22.4679 | T30: 21.3578 | U30: 22.0946 | V30: 21.9859 | W30: 21.6385 | X30: 22.083 | Y30: 21.5833 | Z30: 23.5265 | AA30: 23.4373 | AB30: 23.3486 | AC30: 21.5339 | AD30: 20.6811 | AE30: 18.6525 | AF30: 20.9568 | AG30: 20.5761 | AH30: 20.5142 | AI30: 20.2853 | AJ30: 20.47 | AK30: 20.6779 | AL30: 20.3717
A31: MnO | B31: 0.1255 | C31: 0.1346 | D31: 0.1825 | E31: 0.2555 | F31: 0.0834 | G31: 0.1413 | H31: 0.1342 | I31: 0.1552 | J31: 0.1094 | K31: 0.1551 | L31: 0.1069 | M31: 0.1163 | N31: 0.1173 | O31: 0.1035 | P31: 0.1028 | Q31: 0.1172 | R31: 0.1131 | S31: 0.0872 | T31: 0.1513 | U31: 0 | V31: 0.1096 | W31: 0.1592 | X31: 0.1347 | Y31: 0.1372 | Z31: 0.0991 | AA31: 0.1316 | AB31: 0.1361 | AC31: 0.1235 | AD31: 0.1294 | AE31: 0.0917 | AF31: 0.1613 | AG31: 0.0722 | AH31: 0.1907 | AI31: 0.1785 | AJ31: 0.1695 | AK31: 0.189 | AL31: 0.1702
A32: FeO | B32: 5.5745 | C32: 4.0024 | D32: 4.9596 | E32: 0.7763 | F32: 5.1417 | G32: 5.5017 | H32: 4.7706 | I32: 5.722 | J32: 5.3908 | K32: 5.4798 | L32: 4.9588 | M32: 5.0018 | N32: 5.1876 | O32: 4.8155 | P32: 4.8014 | Q32: 5.0638 | R32: 4.4751 | S32: 1.9948 | T32: 3.5698 | U32: 3.5944 | V32: 4.1052 | W32: 4.0052 | X32: 3.5171 | Y32: 4.1205 | Z32: 1.7441 | AA32: 1.6933 | AB32: 2.0009 | AC32: 3.7364 | AD32: 4.3356 | AE32: 4.7824 | AF32: 5.009 | AG32: 5.5903 | AH32: 5.4599 | AI32: 5.2792 | AJ32: 5.4304 | AK32: 5.082 | AL32: 5.7029
A33: CaO | B33: 11.0178 | C33: 10.1034 | D33: 11.6421 | E33: 23.5811 | F33: 12.8936 | G33: 12.3738 | H33: 13.2878 | I33: 12.2659 | J33: 12.6007 | K33: 12.6079 | L33: 12.9124 | M33: 12.8667 | N33: 12.8802 | O33: 12.8871 | P33: 13.2028 | Q33: 12.3564 | R33: 13.3413 | S33: 13.6642 | T33: 12.5186 | U33: 11.9929 | V33: 13.5372 | W33: 13.3047 | X33: 13.4586 | Y33: 13.2912 | Z33: 13.7817 | AA33: 13.7933 | AB33: 13.7142 | AC33: 13.3988 | AD33: 12.94 | AE33: 12.424 | AF33: 13.1207 | AG33: 12.8061 | AH33: 12.6837 | AI33: 12.4729 | AJ33: 12.5182 | AK33: 12.7437 | AL33: 12.6554
A34: K2O | B34: 0.0576 | C34: 0.0334 | D34: 0.059 | E34: 0.0011 | F34: 0.0171 | G34: 0.0388 | H34: 0.0182 | I34: 0.0502 | J34: 0.0365 | K34: 0.034 | L34: 0.0295 | M34: 0.0364 | N34: 0.0267 | O34: 0.0351 | P34: 0.0114 | Q34: 0.0185 | R34: 0.033 | S34: 0.0125 | T34: 0.039 | U34: 0.036 | V34: 0.0319 | W34: -0.1984 | X34: 0.0217 | Y34: 0.0273 | Z34: 0.0057 | AA34: 0.0115 | AB34: 0.0194 | AC34: 0.0166 | AD34: 0.0361 | AE34: 0.0254 | AF34: 0.0215 | AG34: 0.0364 | AH34: 0.043 | AI34: 0.0389 | AJ34: -0.2065 | AK34: -0.19 | AL34: 0.0328
A35: NiO | B35: 0.1011 | C35: 0.045 | D35: 0.04 | E35: 0.021 | F35: 0.0686 | G35: 0.0817 | H35: 0.1438 | I35: 0.1384 | J35: 0.1015 | K35: 0.1205 | L35: 0.1117 | M35: 0.1509 | N35: 0.1494 | O35: 0.1721 | P35: 0.2035 | Q35: 0.2199 | R35: 0.1801 | S35: 0.0836 | T35: 0.0317 | U35: 0.0581 | V35: 0.0734 | W35: 0.0762 | X35: 0.08 | Y35: 0.0633 | Z35: 0.0889 | AA35: 0.0557 | AB35: 0.0703 | AC35: 0.108 | AD35: 0.0502 | AE35: 0.0742 | AF35: 0.0522 | AG35: 0.0311 | AH35: 0.0256 | AI35: 0.0567 | AJ35: 0.0542 | AK35: 0.0562 | AL35: 0.0271
A36: Total | B36: 96.8915 | C36: 80.2555 | D36: 97.4761 | E36: 94.5482 | F36: 96.749 | G36: 96.9289 | H36: 97.3902 | I36: 96.9884 | J36: 96.6311 | K36: 97.3479 | L36: 97.1955 | M36: 97.1072 | N36: 97.1967 | O36: 97.0757 | P36: 97.2948 | Q36: 96.4153 | R36: 97.4436 | S36: 96.3558 | T36: 96.6074 | U36: 95.8626 | V36: 97.6302 | W36: 96.9839 | X36: 97.3031 | Y36: 97.6818 | Z36: 96.8532 | AA36: 97.0439 | AB36: 97.5024 | AC36: 97.0251 | AD36: 97.1709 | AE36: 95.8571 | AF36: 97.5359 | AG36: 97.2302 | AH36: 97.474 | AI36: 96.8161 | AJ36: 96.9376 | AK36: 97.0162 | AL36: 97.6726
... A39: Z | B39: 30 | C39: -5 | D39: 40 | E39: 47 | F39: -21 | G39: -22 | H39: -22 | I39: -19 | J39: -18 | K39: -28 | L39: -28 | M39: -23 | N39: -23 | O39: 20 | P39: 20 | Q39: 26 | R39: 26 | S39: 65 | T39: 74 | U39: 57 | V39: 58 | W39: 58 | X39: 36 | Y39: 32 | Z39: 39 | AA39: 41 | AB39: 36 | AC39: 68 | AD39: 67 | AE39: 68 | AF39: 4 | AG39: 8 | AH39: 3 | AI39: 48 | AJ39: 50 | AK39: 40 | AL39: 47
A40: Comment | B40: CO1423-2b-amph | C40: CO1423-2a-10amph | D40: CO1423-2a-rep10 | E40: CO1423-4-21amph | F40: CO1418-4coeurband | G40: CO1418-4-amphcoeur | H40: CO1418-4-amphbord | I40: CO1418-4-chl | J40: CO1418-4-chl | K40: CO1418-3b-amph | L40: CO1418-3b-amphbord | M40: CO1418-3b-amphcoeur | N40: CO1418-3b-amphbord | O40: CO1418-1-amph | P40: CO1418-1-amph | Q40: CO1418-1-amph | R40: CO1418-1-amph | S40: CO1429-1a-amph | T40: CO1429-2a-amph | U40: CO1411-2a-amph | V40: CO1411-2a-amphcoeur | W40: CO1411-2a-amphbord | X40: CO1411-1b-amph | Y40: CO1411-1b-amph | Z40: CO1414-2b-amph | AA40: CO1414-2b-amph | AB40: CO1414-2b-amph | AC40: CO1410-5-amph | AD40: CO1410-5-amph | AE40: CO1410-5-amph | AF40: CO1421-1-amph | AG40: CO1421-2c-amphbord | AH40: CO1421-2c-amphbord | AI40: CO1421-3b-amph | AJ40: CO1421-3b-amph | AK40: CO1421-3b-amph | AL40: CO1421-3a-amph
A41: Point# | B41: 1 | C41: 10 | D41: 17 | E41: 22 | F41: 26 | G41: 28 | H41: 29 | I41: 30 | J41: 31 | K41: 34 | L41: 35 | M41: 36 | N41: 37 | O41: 41 | P41: 42 | Q41: 43 | R41: 44 | S41: 49 | T41: 55 | U41: 1 | V41: 2 | W41: 3 | X41: 9 | Y41: 10 | Z41: 15 | AA41: 16 | AB41: 17 | AC41: 25 | AD41: 26 | AE41: 29 | AF41: 38 | AG41: 41 | AH41: 42 | AI41: 46 | AJ41: 47 | AK41: 51 | AL41: 57
A42: Date | B42: 41977.412 | C42: 41977.477 | D42: 41977.545 | E42: 41977.557 | F42: 41977.567 | G42: 41977.572 | H42: 41977.574 | I42: 41977.577 | J42: 41977.579 | K42: 41977.586 | L42: 41977.589 | M42: 41977.591 | N42: 41977.594 | O42: 41977.603 | P42: 41977.606 | Q42: 41977.608 | R42: 41977.611 | S42: 41977.631 | T42: 41977.665 | U42: 41978.411 | V42: 41978.416 | W42: 41978.42 | X42: 41978.443 | Y42: 41978.446 | Z42: 41978.504 | AA42: 41978.506 | AB42: 41978.509 | AC42: 41978.528 | AD42: 41978.53 | AE42: 41978.537 | AF42: 41978.642 | AG42: 41978.649 | AH42: 41978.652 | AI42: 41978.661 | AJ42: 41978.663 | AK42: 41978.673 | AL42: 41978.687

Sheet NAMP
A1: AMPHIBOLE NAMP NORM (stoichiometric, Sum(Cations) = 13+Na+K+Ca, I.e. no Mg/Fe/Mn on M4)
B3: Ox weight | C3: Cat mult | D3: charge
A4: SiO2 | B4: 60.08 | C4: 1 | D4: 4
A5: TiO2 | B5: 79.9 | C5: 1 | D5: 4
A6: Cr2O3 | B6: 151.9908 | C6: 2 | D6: 3
A7: Al2O3 | B7: 101.94 | C7: 2 | D7: 3
A8: FeO | B8: 71.85 | C8: 1 | D8: 2
A9: MnO | B9: 70.937 | C9: 1 | D9: 2
A10: NiO | B10: 74.7094 | C10: 1 | D10: 2
A11: MgO | B11: 40.31 | C11: 1 | D11: 2
A12: CaO | B12: 56.08 | C12: 1 | D12: 2
A13: Na2O | B13: 61.982 | C13: 2 | D13: 1
A14: K2O | B14: 94.2 | C14: 2 | D14: 1
A15: Fe2O3 | B15: 159.691 | C15: 2 | D15: 3
... A18: Cl | B18: 35.453 | C18: 1 | D18: 0
A21: Input | B21: =Input!B1 -> 1 / 1 . | C21: =Input!C1 -> 4 / 1 . | D21: =Input!D1 -> 5 / 1 . | E21: =Input!E1 -> 6 / 1 . | F21: =Input!F1 -> 17 / 1 . | G21: =Input!G1 -> 18 / 1 . | H21: =Input!H1 -> 19 / 1 . | I21: =Input!I1 -> 20 / 1 . | ... T21: =Input!T1 -> 52 / 1 .
B22: =Input!B2 -> YG182_test amph | C22: =Input!C2 -> YG182_1_AmphC | D22: =Input!D2 -> YG182_1_AmphB | E22: =Input!E2 -> YG182_1_AmphB | F22: =Input!F2 -> YG182_2_AmphC | G22: =Input!G2 -> YG182_2_AmphB | H22: =Input!H2 -> YG182_2_AmphC | I22: =Input!I2 -> YG182_2_AmphB | ... T22: =Input!T2 -> 19NC11C_2_AmphB
A23: SiO2 | B23: =Input!B3 -> 46.44 | C23: =Input!C3 -> 45.22 | D23: =Input!D3 -> 44.98 | E23: =Input!E3 -> 44.03 | F23: =Input!F3 -> 44.95 | G23: =Input!G3 -> 44.23 | H23: =Input!H3 -> 44.96 | I23: =Input!I3 -> 45.33 | ... T23: =Input!T3 -> 42.61
A24: TiO2 | B24: =Input!B4 -> 0.44 | C24: =Input!C4 -> 0.55 | D24: =Input!D4 -> 0.57 | E24: =Input!E4 -> 0.39 | F24: =Input!F4 -> 0.62 | G24: =Input!G4 -> 0.58 | H24: =Input!H4 -> 0.6 | I24: =Input!I4 -> 0.61 | ... T24: =Input!T4 -> 1.59
A25: Cr2O3 | B25: =Input!B5 -> 0.05 | C25: =Input!C5 -> 0.04 | D25: =Input!D5 -> 0.03 | E25: =Input!E5 -> 0.05 | F25: =Input!F5 -> 0.03 | G25: =Input!G5 -> 0.02 | H25: =Input!H5 -> 0.07 | I25: =Input!I5 -> 0.05 | ... T25: =Input!T5 -> 0.1
A26: Al2O3 | B26: =Input!B6 -> 9.56 | C26: =Input!C6 -> 11.21 | D26: =Input!D6 -> 11.78 | E26: =Input!E6 -> 11.73 | F26: =Input!F6 -> 11.48 | G26: =Input!G6 -> 11.91 | H26: =Input!H6 -> 11.54 | I26: =Input!I6 -> 11.44 | ... T26: =Input!T6 -> 11.29
A27: FeO | B27: =Input!B7 -> 13.78 | C27: =Input!C7 -> 13.44 | D27: =Input!D7 -> 14.5 | E27: =Input!E7 -> 14.61 | F27: =Input!F7 -> 13.9 | G27: =Input!G7 -> 14.65 | H27: =Input!H7 -> 13.48 | I27: =Input!I7 -> 14.11 | ... T27: =Input!T7 -> 14.68
A28: MnO | B28: =Input!B8 -> 0.68 | C28: =Input!C8 -> 0.84 | D28: =Input!D8 -> 1.01 | E28: =Input!E8 -> 1.11 | F28: =Input!F8 -> 0.85 | G28: =Input!G8 -> 0.84 | H28: =Input!H8 -> 0.81 | I28: =Input!I8 -> 0.85 | ... T28: =Input!T8 -> 0.21
A29: NiO | B29: =Input!B9 -> 0.03 | C29: =Input!C9 -> 0 | D29: =Input!D9 -> 0 | E29: =Input!E9 -> 0.03 | F29: =Input!F9 -> 0 | G29: =Input!G9 -> 0 | H29: =Input!H9 -> 0 | I29: =Input!I9 -> 0 | ... T29: =Input!T9 -> 0
A30: MgO | B30: =Input!B10 -> 12.46 | C30: =Input!C10 -> 13 | D30: =Input!D10 -> 12.06 | E30: =Input!E10 -> 11.98 | F30: =Input!F10 -> 12.24 | G30: =Input!G10 -> 11.92 | H30: =Input!H10 -> 12.39 | I30: =Input!I10 -> 12.42 | ... T30: =Input!T10 -> 11.74
A31: CaO | B31: =Input!B11 -> 10.49 | C31: =Input!C11 -> 10.53 | D31: =Input!D11 -> 10.55 | E31: =Input!E11 -> 10 | F31: =Input!F11 -> 10.87 | G31: =Input!G11 -> 10.94 | H31: =Input!H11 -> 11.02 | I31: =Input!I11 -> 10.81 | ... T31: =Input!T11 -> 12.07
A32: Na2O | B32: =Input!B12 -> 1.35 | C32: =Input!C12 -> 1.4 | D32: =Input!D12 -> 1.51 | E32: =Input!E12 -> 1.39 | F32: =Input!F12 -> 1.39 | G32: =Input!G12 -> 1.47 | H32: =Input!H12 -> 1.37 | I32: =Input!I12 -> 1.41 | ... T32: =Input!T12 -> 1.6
A33: K2O | B33: =Input!B13 -> 0.24 | C33: =Input!C13 -> 0.14 | D33: =Input!D13 -> 0.27 | E33: =Input!E13 -> 0.25 | F33: =Input!F13 -> 0.34 | G33: =Input!G13 -> 0.26 | H33: =Input!H13 -> 0.21 | I33: =Input!I13 -> 0.23 | ... T33: =Input!T13 -> 0.94
A34: H2O | B34: =Input!B14 -> 0 | C34: =Input!C14 -> 0 | D34: =Input!D14 -> 0 | E34: =Input!E14 -> 0 | F34: =Input!F14 -> 0 | G34: =Input!G14 -> 0 | H34: =Input!H14 -> 0 | I34: =Input!I14 -> 0 | ... T34: =Input!T14 -> 0
... A36: Cl | B36: =Input!B16 -> 0 | C36: =Input!C16 -> 0 | D36: =Input!D16 -> 0 | E36: =Input!E16 -> 0 | F36: =Input!F16 -> 0 | G36: =Input!G16 -> 0 | H36: =Input!H16 -> 0 | I36: =Input!I16 -> 0 | ... T36: =Input!T16 -> 0
A38: Total | B38: =SUM(B23:B33) -> 95.52 | C38: =SUM(C23:C33) -> 96.37 | D38: =SUM(D23:D33) -> 97.26 | E38: =SUM(E23:E33) -> 95.57 | F38: =SUM(F23:F33) -> 96.67 | G38: =SUM(G23:G33) -> 96.82 | H38: =SUM(H23:H33) -> 96.45 | I38: =SUM(I23:I33) -> 97.26 | ... T38: =SUM(T23:T33) -> 96.83
A41: Atoms
A42: Si | B42: =B23*$C4/$B4 -> 0.77296937 | C42: =C23*$C4/$B4 -> 0.75266312 | D42: =D23*$C4/$B4 -> 0.74866844 | E42: =E23*$C4/$B4 -> 0.73285619 | F42: =F23*$C4/$B4 -> 0.74816911 | G42: =G23*$C4/$B4 -> 0.73618509 | H42: =H23*$C4/$B4 -> 0.74833555 | I42: =I23*$C4/$B4 -> 0.75449401 | ... T42: =T23*$C4/$B4 -> 0.70922104
A43: Ti | B43: =B24*$C5/$B5 -> 0.0055068836 | C43: =C24*$C5/$B5 -> 0.0068836045 | D43: =D24*$C5/$B5 -> 0.0071339174 | E43: =E24*$C5/$B5 -> 0.0048811014 | F43: =F24*$C5/$B5 -> 0.0077596996 | G43: =G24*$C5/$B5 -> 0.0072590738 | H43: =H24*$C5/$B5 -> 0.0075093867 | I43: =I24*$C5/$B5 -> 0.0076345432 | ... T43: =T24*$C5/$B5 -> 0.019899875
A44: Cr | B44: =B25*$C6/$B6 -> 0.00065793456 | C44: =C25*$C6/$B6 -> 0.00052634765 | D44: =D25*$C6/$B6 -> 0.00039476074 | E44: =E25*$C6/$B6 -> 0.00065793456 | F44: =F25*$C6/$B6 -> 0.00039476074 | G44: =G25*$C6/$B6 -> 0.00026317382 | H44: =H25*$C6/$B6 -> 0.00092110838 | I44: =I25*$C6/$B6 -> 0.00065793456 | ... T44: =T25*$C6/$B6 -> 0.0013158691
A45: Al | B45: =B26*$C7/$B7 -> 0.18756131 | C45: =C26*$C7/$B7 -> 0.21993329 | D45: =D26*$C7/$B7 -> 0.23111634 | E45: =E26*$C7/$B7 -> 0.23013537 | F45: =F26*$C7/$B7 -> 0.22523053 | G45: =G26*$C7/$B7 -> 0.23366686 | H45: =H26*$C7/$B7 -> 0.22640769 | I45: =I26*$C7/$B7 -> 0.22444575 | ... T45: =T26*$C7/$B7 -> 0.22150284
A46: Fe | B46: =B27*$C8/$B8 -> 0.19178845 | C46: =C27*$C8/$B8 -> 0.18705637 | D46: =D27*$C8/$B8 -> 0.20180932 | E46: =E27*$C8/$B8 -> 0.20334029 | F46: =F27*$C8/$B8 -> 0.19345859 | G46: =G27*$C8/$B8 -> 0.20389701 | H46: =H27*$C8/$B8 -> 0.18761308 | I46: =I27*$C8/$B8 -> 0.19638135 | ... T46: =T27*$C8/$B8 -> 0.20431454
A47: Mn | B47: =B28*$C9/$B9 -> 0.0095859707 | C47: =C28*$C9/$B9 -> 0.011841493 | D47: =D28*$C9/$B9 -> 0.014237986 | E47: =E28*$C9/$B9 -> 0.015647687 | F47: =F28*$C9/$B9 -> 0.011982463 | G47: =G28*$C9/$B9 -> 0.011841493 | H47: =H28*$C9/$B9 -> 0.011418583 | I47: =I28*$C9/$B9 -> 0.011982463 | ... T47: =T28*$C9/$B9 -> 0.0029603733
A48: Ni | B48: =B29*$C10/$B10 -> 0.0004015559 | C48: =C29*$C10/$B10 -> 0 | D48: =D29*$C10/$B10 -> 0 | E48: =E29*$C10/$B10 -> 0.0004015559 | F48: =F29*$C10/$B10 -> 0 | G48: =G29*$C10/$B10 -> 0 | H48: =H29*$C10/$B10 -> 0 | I48: =I29*$C10/$B10 -> 0 | ... T48: =T29*$C10/$B10 -> 0
A49: Mg | B49: =B30*$C11/$B11 -> 0.30910444 | C49: =C30*$C11/$B11 -> 0.32250062 | D49: =D30*$C11/$B11 -> 0.29918134 | E49: =E30*$C11/$B11 -> 0.29719673 | F49: =F30*$C11/$B11 -> 0.30364674 | G49: =G30*$C11/$B11 -> 0.29570826 | H49: =H30*$C11/$B11 -> 0.3073679 | I49: =I30*$C11/$B11 -> 0.30811213 | ... T49: =T30*$C11/$B11 -> 0.29124287
...

Sheet CAMP
A1: AMPHIBOLE CAMP NORM (stoichiometric, Sum(Cations) = 15+Na+K, I.e. no Na on M4)
B3: Ox weight | C3: Cat mult | D3: charge
A4: SIO2 | B4: 60.08 | C4: 1 | D4: 4
A5: TIO2 | B5: 79.9 | C5: 1 | D5: 4
A6: Cr2O3 | B6: 151.9908 | C6: 2 | D6: 3
A7: AL2O3 | B7: 101.94 | C7: 2 | D7: 3
A8: FEO | B8: 71.85 | C8: 1 | D8: 2
A9: MNO | B9: 70.937 | C9: 1 | D9: 2
A10: NiO | B10: 74.7094 | C10: 1 | D10: 2
A11: MGO | B11: 40.31 | C11: 1 | D11: 2
A12: CAO | B12: 56.08 | C12: 1 | D12: 2
A13: NA2O | B13: 61.982 | C13: 2 | D13: 1
A14: K2O | B14: 94.2 | C14: 2 | D14: 1
A15: FE2O3 | B15: 159.691 | C15: 2 | D15: 3
... A18: Cl | B18: 35.453 | C18: 1 | D18: 0
A21: Input | B21: =Input!B1 -> 1 / 1 . | C21: =Input!C1 -> 4 / 1 . | D21: =Input!D1 -> 5 / 1 . | E21: =Input!E1 -> 6 / 1 . | F21: =Input!F1 -> 17 / 1 . | G21: =Input!G1 -> 18 / 1 . | H21: =Input!H1 -> 19 / 1 . | I21: =Input!I1 -> 20 / 1 . | ... BL21: =Input!BL1 -> 0 | BN21: Average | BO21: Std
B22: =Input!B2 -> YG182_test amph | C22: =Input!C2 -> YG182_1_AmphC | D22: =Input!D2 -> YG182_1_AmphB | E22: =Input!E2 -> YG182_1_AmphB | F22: =Input!F2 -> YG182_2_AmphC | G22: =Input!G2 -> YG182_2_AmphB | H22: =Input!H2 -> YG182_2_AmphC | I22: =Input!I2 -> YG182_2_AmphB | ... BL22: =Input!BL2 -> 0
A23: SIO2 | B23: =Input!B3 -> 46.44 | C23: =Input!C3 -> 45.22 | D23: =Input!D3 -> 44.98 | E23: =Input!E3 -> 44.03 | F23: =Input!F3 -> 44.95 | G23: =Input!G3 -> 44.23 | H23: =Input!H3 -> 44.96 | I23: =Input!I3 -> 45.33 | ... BL23: =Input!BL3 -> 0 | BN23: =AVERAGE(B23:I23) -> 45.0175 | BO23: =STDEV(B23:I23) -> 0.73355787
A24: TIO2 | B24: =Input!B4 -> 0.44 | C24: =Input!C4 -> 0.55 | D24: =Input!D4 -> 0.57 | E24: =Input!E4 -> 0.39 | F24: =Input!F4 -> 0.62 | G24: =Input!G4 -> 0.58 | H24: =Input!H4 -> 0.6 | I24: =Input!I4 -> 0.61 | ... BL24: =Input!BL4 -> 0 | BN24: =AVERAGE(B24:I24) -> 0.545 | BO24: =STDEV(B24:I24) -> 0.084346225
A25: Cr2O3 | B25: =Input!B5 -> 0.05 | C25: =Input!C5 -> 0.04 | D25: =Input!D5 -> 0.03 | E25: =Input!E5 -> 0.05 | F25: =Input!F5 -> 0.03 | G25: =Input!G5 -> 0.02 | H25: =Input!H5 -> 0.07 | I25: =Input!I5 -> 0.05 | ... BL25: =Input!BL5 -> 0 | BN25: =AVERAGE(B25:I25) -> 0.0425 | BO25: =STDEV(B25:I25) -> 0.015811388
A26: AL2O3 | B26: =Input!B6 -> 9.56 | C26: =Input!C6 -> 11.21 | D26: =Input!D6 -> 11.78 | E26: =Input!E6 -> 11.73 | F26: =Input!F6 -> 11.48 | G26: =Input!G6 -> 11.91 | H26: =Input!H6 -> 11.54 | I26: =Input!I6 -> 11.44 | ... BL26: =Input!BL6 -> 0 | BN26: =AVERAGE(B26:I26) -> 11.33125 | BO26: =STDEV(B26:I26) -> 0.74879785
A27: FEO | B27: =Input!B7 -> 13.78 | C27: =Input!C7 -> 13.44 | D27: =Input!D7 -> 14.5 | E27: =Input!E7 -> 14.61 | F27: =Input!F7 -> 13.9 | G27: =Input!G7 -> 14.65 | H27: =Input!H7 -> 13.48 | I27: =Input!I7 -> 14.11 | ... BL27: =Input!BL7 -> 0 | BN27: =AVERAGE(B27:I27) -> 14.05875 | BO27: =STDEV(B27:I27) -> 0.48865522
A28: MNO | B28: =Input!B8 -> 0.68 | C28: =Input!C8 -> 0.84 | D28: =Input!D8 -> 1.01 | E28: =Input!E8 -> 1.11 | F28: =Input!F8 -> 0.85 | G28: =Input!G8 -> 0.84 | H28: =Input!H8 -> 0.81 | I28: =Input!I8 -> 0.85 | ... BL28: =Input!BL8 -> 0 | BN28: =AVERAGE(B28:I28) -> 0.87375 | BO28: =STDEV(B28:I28) -> 0.13059616
A29: NiO | B29: =Input!B9 -> 0.03 | C29: =Input!C9 -> 0 | D29: =Input!D9 -> 0 | E29: =Input!E9 -> 0.03 | F29: =Input!F9 -> 0 | G29: =Input!G9 -> 0 | H29: =Input!H9 -> 0 | I29: =Input!I9 -> 0 | ... BL29: =Input!BL9 -> 0 | BN29: =AVERAGE(B29:I29) -> 0.0075 | BO29: =STDEV(B29:I29) -> 0.013887301
A30: MGO | B30: =Input!B10 -> 12.46 | C30: =Input!C10 -> 13 | D30: =Input!D10 -> 12.06 | E30: =Input!E10 -> 11.98 | F30: =Input!F10 -> 12.24 | G30: =Input!G10 -> 11.92 | H30: =Input!H10 -> 12.39 | I30: =Input!I10 -> 12.42 | ... BL30: =Input!BL10 -> 0 | BN30: =AVERAGE(B30:I30) -> 12.30875 | BO30: =STDEV(B30:I30) -> 0.34753982
A31: CAO | B31: =Input!B11 -> 10.49 | C31: =Input!C11 -> 10.53 | D31: =Input!D11 -> 10.55 | E31: =Input!E11 -> 10 | F31: =Input!F11 -> 10.87 | G31: =Input!G11 -> 10.94 | H31: =Input!H11 -> 11.02 | I31: =Input!I11 -> 10.81 | ... BL31: =Input!BL11 -> 0 | BN31: =AVERAGE(B31:I31) -> 10.65125 | BO31: =STDEV(B31:I31) -> 0.33112093
A32: NA2O | B32: =Input!B12 -> 1.35 | C32: =Input!C12 -> 1.4 | D32: =Input!D12 -> 1.51 | E32: =Input!E12 -> 1.39 | F32: =Input!F12 -> 1.39 | G32: =Input!G12 -> 1.47 | H32: =Input!H12 -> 1.37 | I32: =Input!I12 -> 1.41 | ... BL32: =Input!BL12 -> 0 | BN32: =AVERAGE(B32:I32) -> 1.41125 | BO32: =STDEV(B32:I32) -> 0.053033009
A33: K2O | B33: =Input!B13 -> 0.24 | C33: =Input!C13 -> 0.14 | D33: =Input!D13 -> 0.27 | E33: =Input!E13 -> 0.25 | F33: =Input!F13 -> 0.34 | G33: =Input!G13 -> 0.26 | H33: =Input!H13 -> 0.21 | I33: =Input!I13 -> 0.23 | ... BL33: =Input!BL13 -> 0 | BN33: =AVERAGE(B33:I33) -> 0.2425 | BO33: =STDEV(B33:I33) -> 0.056505373
A34: H2O | B34: =Input!B14 -> 0 | C34: =Input!C14 -> 0 | D34: =Input!D14 -> 0 | E34: =Input!E14 -> 0 | F34: =Input!F14 -> 0 | G34: =Input!G14 -> 0 | H34: =Input!H14 -> 0 | I34: =Input!I14 -> 0 | ... BL34: =Input!BL14 -> 0 | BN34: =AVERAGE(B34:I34) -> 0 | BO34: =STDEV(B34:I34) -> 0
... A36: Cl | B36: =Input!B16 -> 0 | C36: =Input!C16 -> 0 | D36: =Input!D16 -> 0 | E36: =Input!E16 -> 0 | F36: =Input!F16 -> 0 | G36: =Input!G16 -> 0 | H36: =Input!H16 -> 0 | I36: =Input!I16 -> 0 | ... BL36: =Input!BL16 -> 0 | BN36: =AVERAGE(B36:I36) -> 0 | BO36: =STDEV(B36:I36) -> 0
A38: Total | B38: =SUM(B23:B33) -> 95.52 | C38: =SUM(C23:C33) -> 96.37 | D38: =SUM(D23:D33) -> 97.26 | E38: =SUM(E23:E33) -> 95.57 | F38: =SUM(F23:F33) -> 96.67 | G38: =SUM(G23:G33) -> 96.82 | H38: =SUM(H23:H33) -> 96.45 | I38: =SUM(I23:I33) -> 97.26 | ... BL38: =SUM(BL23:BL33) -> 0 | BN38: =SUM(BN23:BN33) -> 96.49
A41: Atoms
A42: Si | B42: =B23*$C4/$B4 -> 0.77296937 | C42: =C23*$C4/$B4 -> 0.75266312 | D42: =D23*$C4/$B4 -> 0.74866844 | E42: =E23*$C4/$B4 -> 0.73285619 | F42: =F23*$C4/$B4 -> 0.74816911 | G42: =G23*$C4/$B4 -> 0.73618509 | H42: =H23*$C4/$B4 -> 0.74833555 | I42: =I23*$C4/$B4 -> 0.75449401 | ... BJ42: =BJ23*$C4/$B4 -> 0.6960719 | BN42: =BN23*$C4/$B4 -> 0.74929261
A43: Ti | B43: =B24*$C5/$B5 -> 0.0055068836 | C43: =C24*$C5/$B5 -> 0.0068836045 | D43: =D24*$C5/$B5 -> 0.0071339174 | E43: =E24*$C5/$B5 -> 0.0048811014 | F43: =F24*$C5/$B5 -> 0.0077596996 | G43: =G24*$C5/$B5 -> 0.0072590738 | H43: =H24*$C5/$B5 -> 0.0075093867 | I43: =I24*$C5/$B5 -> 0.0076345432 | ... BJ43: =BJ24*$C5/$B5 -> 0.02428035 | BN43: =BN24*$C5/$B5 -> 0.0068210263
A44: Cr | B44: =B25*$C6/$B6 -> 0.00065793456 | C44: =C25*$C6/$B6 -> 0.00052634765 | D44: =D25*$C6/$B6 -> 0.00039476074 | E44: =E25*$C6/$B6 -> 0.00065793456 | F44: =F25*$C6/$B6 -> 0.00039476074 | G44: =G25*$C6/$B6 -> 0.00026317382 | H44: =H25*$C6/$B6 -> 0.00092110838 | I44: =I25*$C6/$B6 -> 0.00065793456 | ... BJ44: =BJ25*$C6/$B6 -> 0.00013158691 | BN44: =BN25*$C6/$B6 -> 0.00055924438
A45: Al | B45: =B26*$C7/$B7 -> 0.18756131 | C45: =C26*$C7/$B7 -> 0.21993329 | D45: =D26*$C7/$B7 -> 0.23111634 | E45: =E26*$C7/$B7 -> 0.23013537 | F45: =F26*$C7/$B7 -> 0.22523053 | G45: =G26*$C7/$B7 -> 0.23366686 | H45: =H26*$C7/$B7 -> 0.22640769 | I45: =I26*$C7/$B7 -> 0.22444575 | ... BJ45: =BJ26*$C7/$B7 -> 0.23013537 | BN45: =BN26*$C7/$B7 -> 0.22231214
A46: Fe | B46: =B27*$C8/$B8 -> 0.19178845 | C46: =C27*$C8/$B8 -> 0.18705637 | D46: =D27*$C8/$B8 -> 0.20180932 | E46: =E27*$C8/$B8 -> 0.20334029 | F46: =F27*$C8/$B8 -> 0.19345859 | G46: =G27*$C8/$B8 -> 0.20389701 | H46: =H27*$C8/$B8 -> 0.18761308 | I46: =I27*$C8/$B8 -> 0.19638135 | ... BJ46: =BJ27*$C8/$B8 -> 0.22811413 | BN46: =BN27*$C8/$B8 -> 0.19566806
A47: Mn | B47: =B28*$C9/$B9 -> 0.0095859707 | C47: =C28*$C9/$B9 -> 0.011841493 | D47: =D28*$C9/$B9 -> 0.014237986 | E47: =E28*$C9/$B9 -> 0.015647687 | F47: =F28*$C9/$B9 -> 0.011982463 | G47: =G28*$C9/$B9 -> 0.011841493 | H47: =H28*$C9/$B9 -> 0.011418583 | I47: =I28*$C9/$B9 -> 0.011982463 | ... BJ47: =BJ28*$C9/$B9 -> 0.0033832838 | BN47: =BN28*$C9/$B9 -> 0.012317267
A48: Ni | B48: =B29*$C10/$B10 -> 0.0004015559 | C48: =C29*$C10/$B10 -> 0 | D48: =D29*$C10/$B10 -> 0 | E48: =E29*$C10/$B10 -> 0.0004015559 | F48: =F29*$C10/$B10 -> 0 | G48: =G29*$C10/$B10 -> 0 | H48: =H29*$C10/$B10 -> 0 | I48: =I29*$C10/$B10 -> 0 | ... BJ48: =BJ29*$C10/$B10 -> 0 | BN48: =BN29*$C10/$B10 -> 0.00010038897
A49: Mg | B49: =B30*$C11/$B11 -> 0.30910444 | C49: =C30*$C11/$B11 -> 0.32250062 | D49: =D30*$C11/$B11 -> 0.29918134 | E49: =E30*$C11/$B11 -> 0.29719673 | F49: =F30*$C11/$B11 -> 0.30364674 | G49: =G30*$C11/$B11 -> 0.29570826 | H49: =H30*$C11/$B11 -> 0.3073679 | I49: =I30*$C11/$B11 -> 0.30811213 | ... BJ49: =BJ30*$C11/$B11 -> 0.24137931 | BN49: =BN30*$C11/$B11 -> 0.30535227
...

Sheet KAMP
A1: AMPHIBOLE CAMP NORM (stoichiometric, Sum(Cations) = 15+K, I.e. no Na on A-site)
B3: Ox weight | C3: Cat mult | D3: charge
A4: SIO2 | B4: 60.08 | C4: 1 | D4: 4
A5: TIO2 | B5: 79.9 | C5: 1 | D5: 4
A6: Cr2O3 | B6: 151.9908 | C6: 2 | D6: 3
A7: AL2O3 | B7: 101.94 | C7: 2 | D7: 3
A8: FEO | B8: 71.85 | C8: 1 | D8: 2
A9: MNO | B9: 70.937 | C9: 1 | D9: 2
A10: NiO | B10: 74.7094 | C10: 1 | D10: 2
A11: MGO | B11: 40.31 | C11: 1 | D11: 2
A12: CAO | B12: 56.08 | C12: 1 | D12: 2
A13: NA2O | B13: 61.982 | C13: 2 | D13: 1
A14: K2O | B14: 94.2 | C14: 2 | D14: 1
A15: FE2O3 | B15: 159.691 | C15: 2 | D15: 3
... A18: Cl | B18: 35.453 | C18: 1 | D18: 0
A21: Input | B21: =Input!B1 -> 1 / 1 . | C21: =Input!C1 -> 4 / 1 . | D21: =Input!D1 -> 5 / 1 . | E21: =Input!E1 -> 6 / 1 . | F21: =Input!F1 -> 17 / 1 . | G21: =Input!G1 -> 18 / 1 . | H21: =Input!H1 -> 19 / 1 . | I21: =Input!I1 -> 20 / 1 . | ... T21: =Input!T1 -> 52 / 1 . | U21: Average | V21: Std
B22: =Input!B2 -> YG182_test amph | C22: =Input!C2 -> YG182_1_AmphC | D22: =Input!D2 -> YG182_1_AmphB | E22: =Input!E2 -> YG182_1_AmphB | F22: =Input!F2 -> YG182_2_AmphC | G22: =Input!G2 -> YG182_2_AmphB | H22: =Input!H2 -> YG182_2_AmphC | I22: =Input!I2 -> YG182_2_AmphB | ... T22: =Input!T2 -> 19NC11C_2_AmphB
A23: SIO2 | B23: =Input!B3 -> 46.44 | C23: =Input!C3 -> 45.22 | D23: =Input!D3 -> 44.98 | E23: =Input!E3 -> 44.03 | F23: =Input!F3 -> 44.95 | G23: =Input!G3 -> 44.23 | H23: =Input!H3 -> 44.96 | I23: =Input!I3 -> 45.33 | ... T23: =Input!T3 -> 42.61 | U23: =AVERAGE(B23:I23) -> 45.0175 | V23: =STDEV(B23:I23) -> 0.73355787
A24: TIO2 | B24: =Input!B4 -> 0.44 | C24: =Input!C4 -> 0.55 | D24: =Input!D4 -> 0.57 | E24: =Input!E4 -> 0.39 | F24: =Input!F4 -> 0.62 | G24: =Input!G4 -> 0.58 | H24: =Input!H4 -> 0.6 | I24: =Input!I4 -> 0.61 | ... T24: =Input!T4 -> 1.59 | U24: =AVERAGE(B24:I24) -> 0.545 | V24: =STDEV(B24:I24) -> 0.084346225
A25: Cr2O3 | B25: =Input!B5 -> 0.05 | C25: =Input!C5 -> 0.04 | D25: =Input!D5 -> 0.03 | E25: =Input!E5 -> 0.05 | F25: =Input!F5 -> 0.03 | G25: =Input!G5 -> 0.02 | H25: =Input!H5 -> 0.07 | I25: =Input!I5 -> 0.05 | ... T25: =Input!T5 -> 0.1 | U25: =AVERAGE(B25:I25) -> 0.0425 | V25: =STDEV(B25:I25) -> 0.015811388
A26: AL2O3 | B26: =Input!B6 -> 9.56 | C26: =Input!C6 -> 11.21 | D26: =Input!D6 -> 11.78 | E26: =Input!E6 -> 11.73 | F26: =Input!F6 -> 11.48 | G26: =Input!G6 -> 11.91 | H26: =Input!H6 -> 11.54 | I26: =Input!I6 -> 11.44 | ... T26: =Input!T6 -> 11.29 | U26: =AVERAGE(B26:I26) -> 11.33125 | V26: =STDEV(B26:I26) -> 0.74879785
A27: FEO | B27: =Input!B7 -> 13.78 | C27: =Input!C7 -> 13.44 | D27: =Input!D7 -> 14.5 | E27: =Input!E7 -> 14.61 | F27: =Input!F7 -> 13.9 | G27: =Input!G7 -> 14.65 | H27: =Input!H7 -> 13.48 | I27: =Input!I7 -> 14.11 | ... T27: =Input!T7 -> 14.68 | U27: =AVERAGE(B27:I27) -> 14.05875 | V27: =STDEV(B27:I27) -> 0.48865522
A28: MNO | B28: =Input!B8 -> 0.68 | C28: =Input!C8 -> 0.84 | D28: =Input!D8 -> 1.01 | E28: =Input!E8 -> 1.11 | F28: =Input!F8 -> 0.85 | G28: =Input!G8 -> 0.84 | H28: =Input!H8 -> 0.81 | I28: =Input!I8 -> 0.85 | ... T28: =Input!T8 -> 0.21 | U28: =AVERAGE(B28:I28) -> 0.87375 | V28: =STDEV(B28:I28) -> 0.13059616
A29: NiO | B29: =Input!B9 -> 0.03 | C29: =Input!C9 -> 0 | D29: =Input!D9 -> 0 | E29: =Input!E9 -> 0.03 | F29: =Input!F9 -> 0 | G29: =Input!G9 -> 0 | H29: =Input!H9 -> 0 | I29: =Input!I9 -> 0 | ... T29: =Input!T9 -> 0 | U29: =AVERAGE(B29:I29) -> 0.0075 | V29: =STDEV(B29:I29) -> 0.013887301
A30: MGO | B30: =Input!B10 -> 12.46 | C30: =Input!C10 -> 13 | D30: =Input!D10 -> 12.06 | E30: =Input!E10 -> 11.98 | F30: =Input!F10 -> 12.24 | G30: =Input!G10 -> 11.92 | H30: =Input!H10 -> 12.39 | I30: =Input!I10 -> 12.42 | ... T30: =Input!T10 -> 11.74 | U30: =AVERAGE(B30:I30) -> 12.30875 | V30: =STDEV(B30:I30) -> 0.34753982
A31: CAO | B31: =Input!B11 -> 10.49 | C31: =Input!C11 -> 10.53 | D31: =Input!D11 -> 10.55 | E31: =Input!E11 -> 10 | F31: =Input!F11 -> 10.87 | G31: =Input!G11 -> 10.94 | H31: =Input!H11 -> 11.02 | I31: =Input!I11 -> 10.81 | ... T31: =Input!T11 -> 12.07 | U31: =AVERAGE(B31:I31) -> 10.65125 | V31: =STDEV(B31:I31) -> 0.33112093
A32: NA2O | B32: =Input!B12 -> 1.35 | C32: =Input!C12 -> 1.4 | D32: =Input!D12 -> 1.51 | E32: =Input!E12 -> 1.39 | F32: =Input!F12 -> 1.39 | G32: =Input!G12 -> 1.47 | H32: =Input!H12 -> 1.37 | I32: =Input!I12 -> 1.41 | ... T32: =Input!T12 -> 1.6 | U32: =AVERAGE(B32:I32) -> 1.41125 | V32: =STDEV(B32:I32) -> 0.053033009
A33: K2O | B33: =Input!B13 -> 0.24 | C33: =Input!C13 -> 0.14 | D33: =Input!D13 -> 0.27 | E33: =Input!E13 -> 0.25 | F33: =Input!F13 -> 0.34 | G33: =Input!G13 -> 0.26 | H33: =Input!H13 -> 0.21 | I33: =Input!I13 -> 0.23 | ... T33: =Input!T13 -> 0.94 | U33: =AVERAGE(B33:I33) -> 0.2425 | V33: =STDEV(B33:I33) -> 0.056505373
A34: H2O | B34: =Input!B14 -> 0 | C34: =Input!C14 -> 0 | D34: =Input!D14 -> 0 | E34: =Input!E14 -> 0 | F34: =Input!F14 -> 0 | G34: =Input!G14 -> 0 | H34: =Input!H14 -> 0 | I34: =Input!I14 -> 0 | ... T34: =Input!T14 -> 0 | U34: =AVERAGE(B34:I34) -> 0 | V34: =STDEV(B34:I34) -> 0
... A36: Cl | B36: =Input!B16 -> 0 | C36: =Input!C16 -> 0 | D36: =Input!D16 -> 0 | E36: =Input!E16 -> 0 | F36: =Input!F16 -> 0 | G36: =Input!G16 -> 0 | H36: =Input!H16 -> 0 | I36: =Input!I16 -> 0 | ... T36: =Input!T16 -> 0 | U36: =AVERAGE(B36:I36) -> 0 | V36: =STDEV(B36:I36) -> 0
A38: Total | B38: =SUM(B23:B33) -> 95.52 | C38: =SUM(C23:C33) -> 96.37 | D38: =SUM(D23:D33) -> 97.26 | E38: =SUM(E23:E33) -> 95.57 | F38: =SUM(F23:F33) -> 96.67 | G38: =SUM(G23:G33) -> 96.82 | H38: =SUM(H23:H33) -> 96.45 | I38: =SUM(I23:I33) -> 97.26 | ... U38: =SUM(U23:U33) -> 96.49
A41: Atoms
A42: Si | B42: =B23*$C4/$B4 -> 0.77296937 | C42: =C23*$C4/$B4 -> 0.75266312 | D42: =D23*$C4/$B4 -> 0.74866844 | E42: =E23*$C4/$B4 -> 0.73285619 | F42: =F23*$C4/$B4 -> 0.74816911 | G42: =G23*$C4/$B4 -> 0.73618509 | H42: =H23*$C4/$B4 -> 0.74833555 | I42: =I23*$C4/$B4 -> 0.75449401 | ... U42: =U23*$C4/$B4 -> 0.74929261
A43: Ti | B43: =B24*$C5/$B5 -> 0.0055068836 | C43: =C24*$C5/$B5 -> 0.0068836045 | D43: =D24*$C5/$B5 -> 0.0071339174 | E43: =E24*$C5/$B5 -> 0.0048811014 | F43: =F24*$C5/$B5 -> 0.0077596996 | G43: =G24*$C5/$B5 -> 0.0072590738 | H43: =H24*$C5/$B5 -> 0.0075093867 | I43: =I24*$C5/$B5 -> 0.0076345432 | ... U43: =U24*$C5/$B5 -> 0.0068210263
A44: Cr | B44: =B25*$C6/$B6 -> 0.00065793456 | C44: =C25*$C6/$B6 -> 0.00052634765 | D44: =D25*$C6/$B6 -> 0.00039476074 | E44: =E25*$C6/$B6 -> 0.00065793456 | F44: =F25*$C6/$B6 -> 0.00039476074 | G44: =G25*$C6/$B6 -> 0.00026317382 | H44: =H25*$C6/$B6 -> 0.00092110838 | I44: =I25*$C6/$B6 -> 0.00065793456 | ... U44: =U25*$C6/$B6 -> 0.00055924438
A45: Al | B45: =B26*$C7/$B7 -> 0.18756131 | C45: =C26*$C7/$B7 -> 0.21993329 | D45: =D26*$C7/$B7 -> 0.23111634 | E45: =E26*$C7/$B7 -> 0.23013537 | F45: =F26*$C7/$B7 -> 0.22523053 | G45: =G26*$C7/$B7 -> 0.23366686 | H45: =H26*$C7/$B7 -> 0.22640769 | I45: =I26*$C7/$B7 -> 0.22444575 | ... U45: =U26*$C7/$B7 -> 0.22231214
A46: Fe | B46: =B27*$C8/$B8 -> 0.19178845 | C46: =C27*$C8/$B8 -> 0.18705637 | D46: =D27*$C8/$B8 -> 0.20180932 | E46: =E27*$C8/$B8 -> 0.20334029 | F46: =F27*$C8/$B8 -> 0.19345859 | G46: =G27*$C8/$B8 -> 0.20389701 | H46: =H27*$C8/$B8 -> 0.18761308 | I46: =I27*$C8/$B8 -> 0.19638135 | ... U46: =U27*$C8/$B8 -> 0.19566806
A47: Mn | B47: =B28*$C9/$B9 -> 0.0095859707 | C47: =C28*$C9/$B9 -> 0.011841493 | D47: =D28*$C9/$B9 -> 0.014237986 | E47: =E28*$C9/$B9 -> 0.015647687 | F47: =F28*$C9/$B9 -> 0.011982463 | G47: =G28*$C9/$B9 -> 0.011841493 | H47: =H28*$C9/$B9 -> 0.011418583 | I47: =I28*$C9/$B9 -> 0.011982463 | ... U47: =U28*$C9/$B9 -> 0.012317267
A48: Ni | B48: =B29*$C10/$B10 -> 0.0004015559 | C48: =C29*$C10/$B10 -> 0 | D48: =D29*$C10/$B10 -> 0 | E48: =E29*$C10/$B10 -> 0.0004015559 | F48: =F29*$C10/$B10 -> 0 | G48: =G29*$C10/$B10 -> 0 | H48: =H29*$C10/$B10 -> 0 | I48: =I29*$C10/$B10 -> 0 | ... U48: =U29*$C10/$B10 -> 0.00010038897
A49: Mg | B49: =B30*$C11/$B11 -> 0.30910444 | C49: =C30*$C11/$B11 -> 0.32250062 | D49: =D30*$C11/$B11 -> 0.29918134 | E49: =E30*$C11/$B11 -> 0.29719673 | F49: =F30*$C11/$B11 -> 0.30364674 | G49: =G30*$C11/$B11 -> 0.29570826 | H49: =H30*$C11/$B11 -> 0.3073679 | I49: =I30*$C11/$B11 -> 0.30811213 | ... U49: =U30*$C11/$B11 -> 0.30535227
...

Sheet RAMP
A1: AMPHIBOLE RAMP NORM 46 charges fixed Fe3+/Fetot ratio provided by input)
B3: Ox weight | C3: Cat mult | D3: charge
A4: SIO2 | B4: 60.08 | C4: 1 | D4: 4
A5: TIO2 | B5: 79.9 | C5: 1 | D5: 4
A6: Cr2O3 | B6: 151.9908 | C6: 2 | D6: 3
A7: AL2O3 | B7: 101.94 | C7: 2 | D7: 3
A8: FEO | B8: 71.85 | C8: 1 | D8: 2
A9: MNO | B9: 70.937 | C9: 1 | D9: 2
A10: NiO | B10: 74.7094 | C10: 1 | D10: 2
A11: MGO | B11: 40.31 | C11: 1 | D11: 2
A12: CAO | B12: 56.08 | C12: 1 | D12: 2
A13: NA2O | B13: 61.982 | C13: 2 | D13: 1
A14: K2O | B14: 94.2 | C14: 2 | D14: 1
A15: FE2O3 | B15: 159.691 | C15: 2 | D15: 3
... A18: Cl | B18: 35.453 | C18: 1 | D18: 0
A21: Input | B21: =Input!B1 -> 1 / 1 . | C21: =Input!C1 -> 4 / 1 . | D21: =Input!D1 -> 5 / 1 . | E21: =Input!E1 -> 6 / 1 . | F21: =Input!F1 -> 17 / 1 . | G21: =Input!G1 -> 18 / 1 . | H21: =Input!H1 -> 19 / 1 . | I21: =Input!I1 -> 20 / 1 . | ... BL21: =Input!BL1 -> 0 | BM21: Average | BN21: Std
B22: =Input!B2 -> YG182_test amph | C22: =Input!C2 -> YG182_1_AmphC | D22: =Input!D2 -> YG182_1_AmphB | E22: =Input!E2 -> YG182_1_AmphB | F22: =Input!F2 -> YG182_2_AmphC | G22: =Input!G2 -> YG182_2_AmphB | H22: =Input!H2 -> YG182_2_AmphC | I22: =Input!I2 -> YG182_2_AmphB | ... BL22: =Input!BL2 -> 0
A23: SIO2 | B23: =Input!B3 -> 46.44 | C23: =Input!C3 -> 45.22 | D23: =Input!D3 -> 44.98 | E23: =Input!E3 -> 44.03 | F23: =Input!F3 -> 44.95 | G23: =Input!G3 -> 44.23 | H23: =Input!H3 -> 44.96 | I23: =Input!I3 -> 45.33 | ... BL23: =Input!BL3 -> 0 | BM23: =AVERAGE(B23:I23) -> 45.0175 | BN23: =STDEV(B23:I23) -> 0.73355787
A24: TIO2 | B24: =Input!B4 -> 0.44 | C24: =Input!C4 -> 0.55 | D24: =Input!D4 -> 0.57 | E24: =Input!E4 -> 0.39 | F24: =Input!F4 -> 0.62 | G24: =Input!G4 -> 0.58 | H24: =Input!H4 -> 0.6 | I24: =Input!I4 -> 0.61 | ... BL24: =Input!BL4 -> 0 | BM24: =AVERAGE(B24:I24) -> 0.545 | BN24: =STDEV(B24:I24) -> 0.084346225
A25: Cr2O3 | B25: =Input!B5 -> 0.05 | C25: =Input!C5 -> 0.04 | D25: =Input!D5 -> 0.03 | E25: =Input!E5 -> 0.05 | F25: =Input!F5 -> 0.03 | G25: =Input!G5 -> 0.02 | H25: =Input!H5 -> 0.07 | I25: =Input!I5 -> 0.05 | ... BL25: =Input!BL5 -> 0 | BM25: =AVERAGE(B25:I25) -> 0.0425 | BN25: =STDEV(B25:I25) -> 0.015811388
A26: AL2O3 | B26: =Input!B6 -> 9.56 | C26: =Input!C6 -> 11.21 | D26: =Input!D6 -> 11.78 | E26: =Input!E6 -> 11.73 | F26: =Input!F6 -> 11.48 | G26: =Input!G6 -> 11.91 | H26: =Input!H6 -> 11.54 | I26: =Input!I6 -> 11.44 | ... BL26: =Input!BL6 -> 0 | BM26: =AVERAGE(B26:I26) -> 11.33125 | BN26: =STDEV(B26:I26) -> 0.74879785
A27: FEO | B27: =Input!B7 -> 13.78 | C27: =Input!C7 -> 13.44 | D27: =Input!D7 -> 14.5 | E27: =Input!E7 -> 14.61 | F27: =Input!F7 -> 13.9 | G27: =Input!G7 -> 14.65 | H27: =Input!H7 -> 13.48 | I27: =Input!I7 -> 14.11 | ... BL27: =Input!BL7 -> 0 | BM27: =AVERAGE(B27:I27) -> 14.05875 | BN27: =STDEV(B27:I27) -> 0.48865522
A28: MNO | B28: =Input!B8 -> 0.68 | C28: =Input!C8 -> 0.84 | D28: =Input!D8 -> 1.01 | E28: =Input!E8 -> 1.11 | F28: =Input!F8 -> 0.85 | G28: =Input!G8 -> 0.84 | H28: =Input!H8 -> 0.81 | I28: =Input!I8 -> 0.85 | ... BL28: =Input!BL8 -> 0 | BM28: =AVERAGE(B28:I28) -> 0.87375 | BN28: =STDEV(B28:I28) -> 0.13059616
A29: NiO | B29: =Input!B9 -> 0.03 | C29: =Input!C9 -> 0 | D29: =Input!D9 -> 0 | E29: =Input!E9 -> 0.03 | F29: =Input!F9 -> 0 | G29: =Input!G9 -> 0 | H29: =Input!H9 -> 0 | I29: =Input!I9 -> 0 | ... BL29: =Input!BL9 -> 0 | BM29: =AVERAGE(B29:I29) -> 0.0075 | BN29: =STDEV(B29:I29) -> 0.013887301
A30: MGO | B30: =Input!B10 -> 12.46 | C30: =Input!C10 -> 13 | D30: =Input!D10 -> 12.06 | E30: =Input!E10 -> 11.98 | F30: =Input!F10 -> 12.24 | G30: =Input!G10 -> 11.92 | H30: =Input!H10 -> 12.39 | I30: =Input!I10 -> 12.42 | ... BL30: =Input!BL10 -> 0 | BM30: =AVERAGE(B30:I30) -> 12.30875 | BN30: =STDEV(B30:I30) -> 0.34753982
A31: CAO | B31: =Input!B11 -> 10.49 | C31: =Input!C11 -> 10.53 | D31: =Input!D11 -> 10.55 | E31: =Input!E11 -> 10 | F31: =Input!F11 -> 10.87 | G31: =Input!G11 -> 10.94 | H31: =Input!H11 -> 11.02 | I31: =Input!I11 -> 10.81 | ... BL31: =Input!BL11 -> 0 | BM31: =AVERAGE(B31:I31) -> 10.65125 | BN31: =STDEV(B31:I31) -> 0.33112093
A32: NA2O | B32: =Input!B12 -> 1.35 | C32: =Input!C12 -> 1.4 | D32: =Input!D12 -> 1.51 | E32: =Input!E12 -> 1.39 | F32: =Input!F12 -> 1.39 | G32: =Input!G12 -> 1.47 | H32: =Input!H12 -> 1.37 | I32: =Input!I12 -> 1.41 | ... BL32: =Input!BL12 -> 0 | BM32: =AVERAGE(B32:I32) -> 1.41125 | BN32: =STDEV(B32:I32) -> 0.053033009
A33: K2O | B33: =Input!B13 -> 0.24 | C33: =Input!C13 -> 0.14 | D33: =Input!D13 -> 0.27 | E33: =Input!E13 -> 0.25 | F33: =Input!F13 -> 0.34 | G33: =Input!G13 -> 0.26 | H33: =Input!H13 -> 0.21 | I33: =Input!I13 -> 0.23 | ... BL33: =Input!BL13 -> 0 | BM33: =AVERAGE(B33:I33) -> 0.2425 | BN33: =STDEV(B33:I33) -> 0.056505373
A34: H2O | B34: =Input!B14 -> 0 | C34: =Input!C14 -> 0 | D34: =Input!D14 -> 0 | E34: =Input!E14 -> 0 | F34: =Input!F14 -> 0 | G34: =Input!G14 -> 0 | H34: =Input!H14 -> 0 | I34: =Input!I14 -> 0 | ... BL34: =Input!BL14 -> 0 | BM34: =AVERAGE(B34:I34) -> 0 | BN34: =STDEV(B34:I34) -> 0
... A36: Cl | B36: =Input!B16 -> 0 | C36: =Input!C16 -> 0 | D36: =Input!D16 -> 0 | E36: =Input!E16 -> 0 | F36: =Input!F16 -> 0 | G36: =Input!G16 -> 0 | H36: =Input!H16 -> 0 | I36: =Input!I16 -> 0 | ... BL36: =Input!BL16 -> 0 | BM36: =AVERAGE(B36:I36) -> 0 | BN36: =STDEV(B36:I36) -> 0
A38: Total | B38: =SUM(B23:B33) -> 95.52 | C38: =SUM(C23:C33) -> 96.37 | D38: =SUM(D23:D33) -> 97.26 | E38: =SUM(E23:E33) -> 95.57 | F38: =SUM(F23:F33) -> 96.67 | G38: =SUM(G23:G33) -> 96.82 | H38: =SUM(H23:H33) -> 96.45 | I38: =SUM(I23:I33) -> 97.26 | ... BM38: =SUM(BM23:BM33) -> 96.49
A41: Atoms
A42: Si | B42: =B23*$C4/$B4 -> 0.77296937 | C42: =C23*$C4/$B4 -> 0.75266312 | D42: =D23*$C4/$B4 -> 0.74866844 | E42: =E23*$C4/$B4 -> 0.73285619 | F42: =F23*$C4/$B4 -> 0.74816911 | G42: =G23*$C4/$B4 -> 0.73618509 | H42: =H23*$C4/$B4 -> 0.74833555 | I42: =I23*$C4/$B4 -> 0.75449401 | ... BK42: =BK23*$C4/$B4 -> 0 | BM42: =BM23*$C4/$B4 -> 0.74929261
A43: Ti | B43: =B24*$C5/$B5 -> 0.0055068836 | C43: =C24*$C5/$B5 -> 0.0068836045 | D43: =D24*$C5/$B5 -> 0.0071339174 | E43: =E24*$C5/$B5 -> 0.0048811014 | F43: =F24*$C5/$B5 -> 0.0077596996 | G43: =G24*$C5/$B5 -> 0.0072590738 | H43: =H24*$C5/$B5 -> 0.0075093867 | I43: =I24*$C5/$B5 -> 0.0076345432 | ... BK43: =BK24*$C5/$B5 -> 0 | BM43: =BM24*$C5/$B5 -> 0.0068210263
A44: Cr | B44: =B25*$C6/$B6 -> 0.00065793456 | C44: =C25*$C6/$B6 -> 0.00052634765 | D44: =D25*$C6/$B6 -> 0.00039476074 | E44: =E25*$C6/$B6 -> 0.00065793456 | F44: =F25*$C6/$B6 -> 0.00039476074 | G44: =G25*$C6/$B6 -> 0.00026317382 | H44: =H25*$C6/$B6 -> 0.00092110838 | I44: =I25*$C6/$B6 -> 0.00065793456 | ... BK44: =BK25*$C6/$B6 -> 0 | BM44: =BM25*$C6/$B6 -> 0.00055924438
A45: Al | B45: =B26*$C7/$B7 -> 0.18756131 | C45: =C26*$C7/$B7 -> 0.21993329 | D45: =D26*$C7/$B7 -> 0.23111634 | E45: =E26*$C7/$B7 -> 0.23013537 | F45: =F26*$C7/$B7 -> 0.22523053 | G45: =G26*$C7/$B7 -> 0.23366686 | H45: =H26*$C7/$B7 -> 0.22640769 | I45: =I26*$C7/$B7 -> 0.22444575 | ... BK45: =BK26*$C7/$B7 -> 0 | BM45: =BM26*$C7/$B7 -> 0.22231214
A46: Fe3+ | B46: =B27*$C8*Input!$B20/$B8 -> 0.03835769 | C46: =C27*$C8*Input!$B20/$B8 -> 0.037411273 | D46: =D27*$C8*Input!$B20/$B8 -> 0.040361865 | E46: =E27*$C8*Input!$B20/$B8 -> 0.040668058 | F46: =F27*$C8*Input!$B20/$B8 -> 0.038691719 | G46: =G27*$C8*Input!$B20/$B8 -> 0.040779402 | H46: =H27*$C8*Input!$B20/$B8 -> 0.037522617 | I46: =I27*$C8*Input!$B20/$B8 -> 0.03927627 | ... BK46: =BK27*$C8*Input!$B20/$B8 -> 0 | BM46: =BM27*$C8*Input!$B20/$B8 -> 0.039133612
A47: Fe2+ | B47: =B27*$C8*(1-Input!$B20)/$B8 -> 0.15343076 | C47: =C27*$C8*(1-Input!$B20)/$B8 -> 0.14964509 | D47: =D27*$C8*(1-Input!$B20)/$B8 -> 0.16144746 | E47: =E27*$C8*(1-Input!$B20)/$B8 -> 0.16267223 | F47: =F27*$C8*(1-Input!$B20)/$B8 -> 0.15476688 | G47: =G27*$C8*(1-Input!$B20)/$B8 -> 0.16311761 | H47: =H27*$C8*(1-Input!$B20)/$B8 -> 0.15009047 | I47: =I27*$C8*(1-Input!$B20)/$B8 -> 0.15710508 | ... BK47: =BK27*$C8*(1-Input!$B20)/$B8 -> 0 | BM47: =BM27*$C8*(1-Input!$B20)/$B8 -> 0.15653445
A48: Mn | B48: =B28*$C9/$B9 -> 0.0095859707 | C48: =C28*$C9/$B9 -> 0.011841493 | D48: =D28*$C9/$B9 -> 0.014237986 | E48: =E28*$C9/$B9 -> 0.015647687 | F48: =F28*$C9/$B9 -> 0.011982463 | G48: =G28*$C9/$B9 -> 0.011841493 | H48: =H28*$C9/$B9 -> 0.011418583 | I48: =I28*$C9/$B9 -> 0.011982463 | ... BK48: =BK28*$C9/$B9 -> 0 | BM48: =BM28*$C9/$B9 -> 0.012317267
A49: Ni | B49: =B29*$C10/$B10 -> 0.0004015559 | C49: =C29*$C10/$B10 -> 0 | D49: =D29*$C10/$B10 -> 0 | E49: =E29*$C10/$B10 -> 0.0004015559 | F49: =F29*$C10/$B10 -> 0 | G49: =G29*$C10/$B10 -> 0 | H49: =H29*$C10/$B10 -> 0 | I49: =I29*$C10/$B10 -> 0 | ... BK49: =BK29*$C10/$B10 -> 0 | BM49: =BM29*$C10/$B10 -> 0.00010038897
...

Sheet AN
B1: Amphibole Names
A3: 3 | B3: Mg-Anth/Cumm
A4: 4 | B4: Anth/Cumm
A5: 5 | B5: Ferro-Anth/Grunerite
A6: 6 | B6: Mg-Gedrite/Cumm
A7: 7 | B7: Gedrite/Cumm
A8: 8 | B8: Ferro-Gedrite/Cumm
A9: 9 | B9: Kaersutite
A10: 10 | B10: Ferro-Kaersutite
A11: 11 | B11: Tremolite
A12: 12 | B12: Actinolite
A13: 13 | B13: Ferro-Actinolite
A14: 14 | B14: Tremolitic Hbl
... A65: 65 | B65: Riebeckite

Sheet pu378 amp
A1: Sample | B1: pu397 amp1 | C1: pu397 amp2 | D1: pu397 amp3 | E1: pu397 amp4 | F1: pu397 amp5 | G1: pu397 amph6
A3: SiO2 | B3: 41.398 | C3: 40.155 | D3: 41.291 | E3: 42.217 | F3: 42.324 | G3: 42.97
A4: TiO2 | B4: 2.168 | C4: 2.569 | D4: 2.257 | E4: 2.063 | F4: 2.012 | G4: 2.233
A5: Cr2O3 | B5: 0.012 | C5: 0.012 | D5: 0.022 | E5: 0.023 | F5: 0 | G5: 0.025
A6: Al2O3 | B6: 14.983 | C6: 14.857 | D6: 14.056 | E6: 13.572 | F6: 13.952 | G6: 14.995
A7: FeO | B7: 8.129 | C7: 8.995 | D7: 7.764 | E7: 7.517 | F7: 7.669 | G7: 7.46
A8: MnO | B8: 0.046 | C8: 0.04 | D8: 0.017 | E8: 0.037 | F8: 0.127 | G8: 0.07
A9: NiO | B9: 0 | C9: 0 | D9: 0 | E9: 0 | F9: 0 | G9: 0
A10: MgO | B10: 15.059 | C10: 14.205 | D10: 15.976 | E10: 15.644 | F10: 15.639 | G10: 15.208
A11: CaO | B11: 10.791 | C11: 11.062 | D11: 10.499 | E11: 10.555 | F11: 10.453 | G11: 10.291
A12: Na2O | B12: 2.638 | C12: 2.561 | D12: 2.809 | E12: 2.676 | F12: 2.624 | G12: 2.569
A13: K2O | B13: 2.001 | C13: 1.855 | D13: 2 | E13: 2.149 | F13: 2.215 | G13: 2.257
B14: =SUM(B3:B13) -> 97.225 | C14: =SUM(C3:C13) -> 96.311 | D14: =SUM(D3:D13) -> 96.691 | E14: =SUM(E3:E13) -> 96.453 | F14: =SUM(F3:F13) -> 97.015 | G14: =SUM(G3:G13) -> 98.078

Sheet pu380 amp
B1: pu380 | C1: pu380 | D1: pu380 | E1: pu380 | F1: pu380 | G1: pu380 | H1: pu380 | I1: pu380
B2: amph | C2: amph | D2: amph | E2: amph | F2: amph | G2: amph | H2: amph | I2: amph
A3: SiO2 | B3: 41.193 | C3: 40.161 | D3: 41.68 | E3: 40.906 | F3: 40.384 | G3: 42.213 | H3: 40.84 | I3: 41.053
A4: TiO2 | B4: 3.623 | C4: 3.546 | D4: 3.071 | E4: 3.826 | F4: 3.806 | G4: 2.926 | H4: 3.463 | I4: 3.54
A5: Cr2O3 | B5: 0.047 | C5: 0.039 | D5: 0.08 | E5: 0.029 | F5: 0.025 | G5: 0 | H5: 0.072 | I5: 0.212
A6: Al2O3 | B6: 14.562 | C6: 14.477 | D6: 13.512 | E6: 14.615 | F6: 14.324 | G6: 13.415 | H6: 14.602 | I6: 14.713
A7: FeO | B7: 9.08 | C7: 9.043 | D7: 9.632 | E7: 9.131 | F7: 9.416 | G7: 9.637 | H7: 9.158 | I7: 9.234
A8: MnO | B8: 0.093 | C8: 0.103 | D8: 0.099 | E8: 0.084 | F8: 0.186 | G8: 0.137 | H8: 0.133 | I8: 0.195
A9: NiO | B9: 0 | C9: 0.025 | D9: 0.136 | E9: 0.12 | F9: 0.039 | G9: 0.104 | H9: 0 | I9: 0.018
A10: MgO | B10: 14.404 | C10: 14.372 | D10: 14.613 | E10: 14.442 | F10: 14.014 | G10: 14.827 | H10: 14.512 | I10: 14.548
A11: CaO | B11: 11.353 | C11: 11.568 | D11: 10.968 | E11: 11.445 | F11: 11.487 | G11: 11.014 | H11: 11.366 | I11: 11.325
A12: Na2O | B12: 2.568 | C12: 2.521 | D12: 2.554 | E12: 2.584 | F12: 2.445 | G12: 2.568 | H12: 2.531 | I12: 2.529
A13: K2O | B13: 1.371 | C13: 1.436 | D13: 1.598 | E13: 1.312 | F13: 1.366 | G13: 1.571 | H13: 1.403 | I13: 1.431
A14: H2O | B14: 0 | C14: 0 | D14: 0 | E14: 0 | F14: 0 | G14: 0 | H14: 0 | I14: 0
... A16: Cl | B16: 0 | C16: 0 | D16: 0 | E16: 0 | F16: 0 | G16: 0 | H16: 0 | I16: 0
B17: =SUM(B3:B13) -> 98.294 | C17: =SUM(C3:C13) -> 97.291 | D17: =SUM(D3:D13) -> 97.943 | E17: =SUM(E3:E13) -> 98.494 | F17: =SUM(F3:F13) -> 97.492 | G17: =SUM(G3:G13) -> 98.412 | H17: =SUM(H3:H13) -> 98.08 | I17: =SUM(I3:I13) -> 98.798
