Workbook

Sheet Input
B1: 2 / 1 . | C1: 3 / 1 . | D1: 9 / 1 . | E1: 10 / 1 . | F1: 11 / 1 . | G1: 12 / 1 . | H1: 13 / 1 . | I1: 14 / 1 . | J1: 21 / 1 . | K1: 22 / 1 . | L1: 23 / 1 . | M1: 24 / 1 . | N1: 25 / 1 . | O1: 21 / 1 . | P1: 22 / 1 . | Q1: 23 / 1 . | R1: 24 / 1 . | S1: 25 / 1 . | T1: 36 / 1 . | U1: 37 / 1 . | V1: 38 / 1 . | W1: 39 / 1 .
B2: YG182_1_Gt | C2: YG182_1_Gt | D2: YG182_1_GtC | E2: YG182_1_GtB | F2: YG182_1_GtC | G2: YG182_1_GtB | H2: YG182_2_GtC | I2: YG182_2_GtB | J2: YG182_2_GrtC | K2: YG182_2_GrtB | L2: YG182_2_GrtC | M2: YG182_2_GrtB | N2: YG182_2_GrtB | O2: YG182_2_GrtC | P2: YG182_2_GrtB | Q2: YG182_2_GrtC | R2: YG182_2_GrtB | S2: YG182_2_GrtB | T2: YG182_1_GtC | U2: YG182_1_GtB | V2: YG182_1_GtC | W2: YG182_1_GtB
A3: SiO2 | B3: 36.86 | C3: 37.56 | D3: 37.23 | E3: 37.65 | F3: 36.76 | G3: 37.67 | H3: 36.83 | I3: 37.11 | J3: 37.19 | K3: 37.46 | L3: 37.2 | M3: 37.35 | N3: 36.84 | O3: 37.19 | P3: 37.46 | Q3: 37.2 | R3: 37.35 | S3: 36.84 | T3: 37.09 | U3: 36.91 | V3: 37.23 | W3: 37.63
A4: TiO2 | B4: 0.28 | C4: 0.06 | D4: 0.22 | E4: 0.07 | F4: 0.31 | G4: 0.13 | H4: 0.11 | I4: 0.06 | J4: 0.08 | K4: 0.11 | L4: 0.06 | M4: 0.06 | N4: 0.55 | O4: 0.08 | P4: 0.11 | Q4: 0.06 | R4: 0.06 | S4: 0.55 | T4: 0.2 | U4: 0.09 | V4: 0.55 | W4: 0.05
A5: Cr2O3 | B5: 0 | C5: 0.01 | D5: 0.01 | E5: 0 | F5: 0 | G5: 0.01 | H5: 0 | I5: 0 | J5: 0.02 | K5: 0.02 | L5: 0 | M5: 0 | N5: 0.01 | O5: 0.02 | P5: 0.02 | Q5: 0 | R5: 0 | S5: 0.01 | T5: 0 | U5: 0.03 | V5: 0 | W5: 0.03
A6: Al2O3 | B6: 20.19 | C6: 21.12 | D6: 20.18 | E6: 20.98 | F6: 20 | G6: 21.1 | H6: 20.52 | I6: 20.42 | J6: 20.8 | K6: 20.82 | L6: 20.51 | M6: 20.83 | N6: 19.45 | O6: 20.8 | P6: 20.82 | Q6: 20.51 | R6: 20.83 | S6: 19.45 | T6: 20.02 | U6: 20.2 | V6: 20.02 | W6: 20.64
A7: FeO | B7: 20.36 | C7: 23.26 | D7: 19.66 | E7: 20.36 | F7: 8.88 | G7: 20.46 | H7: 19.65 | I7: 18.24 | J7: 18.39 | K7: 21.68 | L7: 17.55 | M7: 21.47 | N7: 19.16 | O7: 18.39 | P7: 21.68 | Q7: 17.55 | R7: 21.47 | S7: 19.16 | T7: 20.97 | U7: 17.66 | V7: 21.75 | W7: 21.38
A8: MnO | B8: 16.95 | C8: 12.57 | D8: 18.56 | E8: 16.64 | F8: 30.15 | G8: 15.01 | H8: 19.07 | I8: 20.02 | J8: 20.08 | K8: 13.58 | L8: 21.19 | M8: 13.71 | N8: 20.34 | O8: 20.08 | P8: 13.58 | Q8: 21.19 | R8: 13.71 | S8: 20.34 | T8: 16.42 | U8: 19.97 | V8: 15.13 | W8: 14.99
A9: NiO
A10: MgO | B10: 3.72 | C10: 4.49 | D10: 3.36 | E10: 3.99 | F10: 2.73 | G10: 4.03 | H10: 3.15 | I10: 3.33 | J10: 3.19 | K10: 4.23 | L10: 3.08 | M10: 4.26 | N10: 3.19 | O10: 3.19 | P10: 4.23 | Q10: 3.08 | R10: 4.26 | S10: 3.19 | T10: 3.99 | U10: 3.57 | V10: 4.02 | W10: 4.29
A11: CaO | B11: 1.37 | C11: 1.83 | D11: 1.21 | E11: 1.12 | F11: 1.17 | G11: 2.27 | H11: 1.3 | I11: 1.02 | J11: 1.14 | K11: 2.27 | L11: 1.13 | M11: 1.88 | N11: 1.01 | O11: 1.14 | P11: 2.27 | Q11: 1.13 | R11: 1.88 | S11: 1.01 | T11: 1.27 | U11: 1.25 | V11: 1.54 | W11: 1.25
A12: Na2O | B12: 0.04 | C12: 0 | D12: 0.04 | E12: 0.04 | F12: 0 | G12: 0.03 | H12: 0 | I12: 0.05 | J12: 0.03 | K12: 0.04 | L12: 0.03 | M12: 0.02 | N12: 0.03 | O12: 0.03 | P12: 0.04 | Q12: 0.03 | R12: 0.02 | S12: 0.03 | T12: 0.02 | U12: 0.05 | V12: 0 | W12: 0.05
A13: K2O | B13: 0.03 | C13: 0 | D13: 0 | E13: 0 | F13: 0 | G13: 0 | H13: 0.01 | I13: 0.01 | J13: 0 | K13: 0 | L13: 0.01 | M13: 0 | N13: 0 | O13: 0 | P13: 0 | Q13: 0.01 | R13: 0 | S13: 0 | T13: 0 | U13: 0 | V13: 0.01 | W13: 0
A14: =B39 -> Add ox | B14: 0 | C14: 0 | D14: 0 | E14: 0 | F14: 0 | G14: 0 | H14: 0 | I14: 0 | J14: 0 | K14: 0 | L14: 0 | M14: 0 | N14: 0 | O14: 0 | P14: 0 | Q14: 0 | R14: 0 | S14: 0 | T14: 0 | U14: 0 | V14: 0 | W14: 0
A15: H2O | B15: 0 | C15: 0 | D15: 0 | E15: 0 | F15: 0 | G15: 0 | H15: 0 | I15: 0 | J15: 0 | K15: 0 | L15: 0 | M15: 0 | N15: 0 | O15: 0 | P15: 0 | Q15: 0 | R15: 0 | S15: 0 | T15: 0 | U15: 0 | V15: 0 | W15: 0
A16: F | B16: 0 | C16: 0 | D16: 0 | E16: 0 | F16: 0 | G16: 0 | H16: 0 | I16: 0 | J16: 0 | K16: 0 | L16: 0 | M16: 0 | N16: 0 | O16: 0 | P16: 0 | Q16: 0 | R16: 0 | S16: 0 | T16: 0 | U16: 0 | V16: 0 | W16: 0
A17: Cl | B17: 0 | C17: 0 | D17: 0 | E17: 0 | F17: 0 | G17: 0 | H17: 0 | I17: 0 | J17: 0 | K17: 0 | L17: 0 | M17: 0 | N17: 0 | O17: 0 | P17: 0 | Q17: 0 | R17: 0 | S17: 0 | T17: 0 | U17: 0 | V17: 0 | W17: 0
A18: Total | B18: =SUM(B3:B17) -> 99.8 | C18: =SUM(C3:C17) -> 100.9 | D18: =SUM(D3:D17) -> 100.47 | E18: =SUM(E3:E17) -> 100.85 | F18: =SUM(F3:F17) -> 100 | G18: =SUM(G3:G17) -> 100.71 | H18: =SUM(H3:H17) -> 100.64 | I18: =SUM(I3:I17) -> 100.26 | ... W18: =SUM(W3:W17) -> 100.31
F20: Biotite | G20: Muscovite | H20: Liquids
A21: Number OXYGENS | B21: 12 | D21: Total charges/2 | F21: 11 | G21: 11 | H21: 100 | J21: NB: number of oxygens = total number of oxygens including oxygens from OH
A25: Fe3+/Fetot | B25: 0 | F25: 0 | G25: 0 | H25: 0
A29: Number OH-sites | B29: 0 | F29: 2 | G29: 2 | H29: 0
A36: Additional Element (for HFSE-partitioning runs)
A38: Element | B38: Formula | C38: Ox weight | D38: Cat mult | E38: charge
A39: Add El | B39: Add ox | C39: 441.893 | D39: 2 | E39: 5
C43: Form wt. | D43: #Cat | E43: *Ox | F43: #Ox | G43: El. Weight | H43: Oxygen
A44: Y | B44: Y2O3 | C44: =D44*G44+F44*H44 -> 225.8082 | D44: 2 | E44: 3 | F44: 3 | G44: 88.905 | H44: 15.9994
A45: Sc | B45: Sc2O3 | C45: =D45*G45+F45*H45 -> 137.9102 | D45: 2 | E45: 3 | F45: 3 | G45: 44.956 | H45: 15.9994
A46: V | B46: V2O5 | C46: =D46*G46+F46*H46 -> 181.881 | D46: 2 | E46: 5 | F46: 5 | G46: 50.942 | H46: 15.9994
A47: P | B47: P2O5 | C47: =D47*G47+F47*H47 -> 141.9446 | D47: 2 | E47: 5 | F47: 5 | G47: 30.9738 | H47: 15.9994
A48: Zr | B48: ZrO2 | C48: =D48*G48+F48*H48 -> 123.2188 | D48: 1 | E48: 4 | F48: 2 | G48: 91.22 | H48: 15.9994
A49: Nb | B49: Nb2O5 | C49: =D49*G49+E49*H49 -> 265.809 | D49: 2 | E49: 5 | F49: 2 | G49: 92.906 | H49: 15.9994
A50: Hf | B50: HfO2 | C50: =D50*G50+E50*H50 -> 210.4888 | D50: 1 | E50: 2 | F50: 2 | G50: 178.49 | H50: 15.9994
A51: Ta | B51: Ta2O5 | C51: =D51*G51+E51*H51 -> 441.893 | D51: 2 | E51: 5 | F51: 5 | G51: 180.948 | H51: 15.9994

Sheet General oxygen
A1: General Oxygen NORM (number oxygens and OH-sites given in Input)
B3: Ox weight | C3: Cat mult | D3: charge | F3: #Oxygens | G3: =Input!B21 -> 12
A4: SiO2 | B4: 60.08 | C4: 1 | D4: 4 | F4: Fe3+/Fetot | G4: =Input!B25 -> 0
A5: TiO2 | B5: 79.9 | C5: 1 | D5: 4 | F5: #OH-sites | G5: =Input!B29 -> 0
A6: Cr2O3 | B6: 151.9908 | C6: 2 | D6: 3
A7: Al2O3 | B7: 101.94 | C7: 2 | D7: 3
A8: FeO | B8: 71.85 | C8: 1 | D8: 2
A9: MnO | B9: 70.937 | C9: 1 | D9: 2
A10: NiO | B10: 74.7094 | C10: 1 | D10: 2
A11: MgO | B11: 40.31 | C11: 1 | D11: 2
A12: CaO | B12: 56.08 | C12: 1 | D12: 2
A13: Na2O | B13: 61.982 | C13: 2 | D13: 1
A14: K2O | B14: 94.2 | C14: 2 | D14: 1
A15: Fe2O3 | B15: 159.691 | C15: 2 | D15: 3
A16: =Input!B39 -> Add ox | B16: =Input!C39 -> 441.893 | C16: =Input!D39 -> 2 | D16: =Input!E39 -> 5
A17: H2O | B17: 18.01534 | C17: 2 | D17: 0
A18: F | B18: 18.9984 | C18: 1 | D18: 0
A19: Cl | B19: 35.453 | C19: 1 | D19: 0
A22: Input | B22: =Input!B1 -> 2 / 1 . | C22: =Input!C1 -> 3 / 1 . | D22: =Input!D1 -> 9 / 1 . | E22: =Input!E1 -> 10 / 1 . | F22: =Input!F1 -> 11 / 1 . | G22: =Input!G1 -> 12 / 1 . | H22: =Input!H1 -> 13 / 1 . | I22: =Input!I1 -> 14 / 1 . | ... AD22: =Input!AD1 -> 0
B23: =Input!B2 -> YG182_1_Gt | C23: =Input!C2 -> YG182_1_Gt | D23: =Input!D2 -> YG182_1_GtC | E23: =Input!E2 -> YG182_1_GtB | F23: =Input!F2 -> YG182_1_GtC | G23: =Input!G2 -> YG182_1_GtB | H23: =Input!H2 -> YG182_2_GtC | I23: =Input!I2 -> YG182_2_GtB | ... AD23: =Input!AD2 -> 0
A24: SiO2 | B24: =Input!B3 -> 36.86 | C24: =Input!C3 -> 37.56 | D24: =Input!D3 -> 37.23 | E24: =Input!E3 -> 37.65 | F24: =Input!F3 -> 36.76 | G24: =Input!G3 -> 37.67 | H24: =Input!H3 -> 36.83 | I24: =Input!I3 -> 37.11 | ... AD24: =Input!AD3 -> 0
A25: TiO2 | B25: =Input!B4 -> 0.28 | C25: =Input!C4 -> 0.06 | D25: =Input!D4 -> 0.22 | E25: =Input!E4 -> 0.07 | F25: =Input!F4 -> 0.31 | G25: =Input!G4 -> 0.13 | H25: =Input!H4 -> 0.11 | I25: =Input!I4 -> 0.06 | ... AD25: =Input!AD4 -> 0
A26: Cr2O3 | B26: =Input!B5 -> 0 | C26: =Input!C5 -> 0.01 | D26: =Input!D5 -> 0.01 | E26: =Input!E5 -> 0 | F26: =Input!F5 -> 0 | G26: =Input!G5 -> 0.01 | H26: =Input!H5 -> 0 | I26: =Input!I5 -> 0 | ... AD26: =Input!AD5 -> 0
A27: Al2O3 | B27: =Input!B6 -> 20.19 | C27: =Input!C6 -> 21.12 | D27: =Input!D6 -> 20.18 | E27: =Input!E6 -> 20.98 | F27: =Input!F6 -> 20 | G27: =Input!G6 -> 21.1 | H27: =Input!H6 -> 20.52 | I27: =Input!I6 -> 20.42 | ... AD27: =Input!AD6 -> 0
A28: FeO | B28: =Input!B7 -> 20.36 | C28: =Input!C7 -> 23.26 | D28: =Input!D7 -> 19.66 | E28: =Input!E7 -> 20.36 | F28: =Input!F7 -> 8.88 | G28: =Input!G7 -> 20.46 | H28: =Input!H7 -> 19.65 | I28: =Input!I7 -> 18.24 | ... AD28: =Input!AD7 -> 0
A29: MnO | B29: =Input!B8 -> 16.95 | C29: =Input!C8 -> 12.57 | D29: =Input!D8 -> 18.56 | E29: =Input!E8 -> 16.64 | F29: =Input!F8 -> 30.15 | G29: =Input!G8 -> 15.01 | H29: =Input!H8 -> 19.07 | I29: =Input!I8 -> 20.02 | ... AD29: =Input!AD8 -> 0
A30: NiO | B30: =Input!B9 -> 0 | C30: =Input!C9 -> 0 | D30: =Input!D9 -> 0 | E30: =Input!E9 -> 0 | F30: =Input!F9 -> 0 | G30: =Input!G9 -> 0 | H30: =Input!H9 -> 0 | I30: =Input!I9 -> 0 | ... AD30: =Input!AD9 -> 0
A31: MgO | B31: =Input!B10 -> 3.72 | C31: =Input!C10 -> 4.49 | D31: =Input!D10 -> 3.36 | E31: =Input!E10 -> 3.99 | F31: =Input!F10 -> 2.73 | G31: =Input!G10 -> 4.03 | H31: =Input!H10 -> 3.15 | I31: =Input!I10 -> 3.33 | ... AD31: =Input!AD10 -> 0
A32: CaO | B32: =Input!B11 -> 1.37 | C32: =Input!C11 -> 1.83 | D32: =Input!D11 -> 1.21 | E32: =Input!E11 -> 1.12 | F32: =Input!F11 -> 1.17 | G32: =Input!G11 -> 2.27 | H32: =Input!H11 -> 1.3 | I32: =Input!I11 -> 1.02 | ... AD32: =Input!AD11 -> 0
A33: Na2O | B33: =Input!B12 -> 0.04 | C33: =Input!C12 -> 0 | D33: =Input!D12 -> 0.04 | E33: =Input!E12 -> 0.04 | F33: =Input!F12 -> 0 | G33: =Input!G12 -> 0.03 | H33: =Input!H12 -> 0 | I33: =Input!I12 -> 0.05 | ... AD33: =Input!AD12 -> 0
A34: K2O | B34: =Input!B13 -> 0.03 | C34: =Input!C13 -> 0 | D34: =Input!D13 -> 0 | E34: =Input!E13 -> 0 | F34: =Input!F13 -> 0 | G34: =Input!G13 -> 0 | H34: =Input!H13 -> 0.01 | I34: =Input!I13 -> 0.01 | ... AD34: =Input!AD13 -> 0
A35: =A16 -> Add ox | B35: =Input!B14 -> 0 | C35: =Input!C14 -> 0 | D35: =Input!D14 -> 0 | E35: =Input!E14 -> 0 | F35: =Input!F14 -> 0 | G35: =Input!G14 -> 0 | H35: =Input!H14 -> 0 | I35: =Input!I14 -> 0 | ... AD35: =Input!AD14 -> 0
A36: H2O | B36: =Input!B15 -> 0 | C36: =Input!C15 -> 0 | D36: =Input!D15 -> 0 | E36: =Input!E15 -> 0 | F36: =Input!F15 -> 0 | G36: =Input!G15 -> 0 | H36: =Input!H15 -> 0 | I36: =Input!I15 -> 0 | ... AD36: =Input!AD15 -> 0
A37: F | B37: =Input!B16 -> 0 | C37: =Input!C16 -> 0 | D37: =Input!D16 -> 0 | E37: =Input!E16 -> 0 | F37: =Input!F16 -> 0 | G37: =Input!G16 -> 0 | H37: =Input!H16 -> 0 | I37: =Input!I16 -> 0 | ... AD37: =Input!AD16 -> 0
A38: Cl | B38: =Input!B17 -> 0 | C38: =Input!C17 -> 0 | D38: =Input!D17 -> 0 | E38: =Input!E17 -> 0 | F38: =Input!F17 -> 0 | G38: =Input!G17 -> 0 | H38: =Input!H17 -> 0 | I38: =Input!I17 -> 0 | ... AD38: =Input!AD17 -> 0
A40: Total | B40: =SUM(B24:B35) -> 99.8 | C40: =SUM(C24:C35) -> 100.9 | D40: =SUM(D24:D35) -> 100.47 | E40: =SUM(E24:E35) -> 100.85 | F40: =SUM(F24:F35) -> 100 | G40: =SUM(G24:G35) -> 100.71 | H40: =SUM(H24:H35) -> 100.64 | I40: =SUM(I24:I35) -> 100.26 | ... AD40: =SUM(AD24:AD35) -> 0
A43: Atoms
A44: Si | B44: =B24*$C4/$B4 -> 0.61351531 | C44: =C24*$C4/$B4 -> 0.62516644 | D44: =D24*$C4/$B4 -> 0.61967377 | E44: =E24*$C4/$B4 -> 0.62666445 | F44: =F24*$C4/$B4 -> 0.61185087 | G44: =G24*$C4/$B4 -> 0.62699734 | H44: =H24*$C4/$B4 -> 0.61301598 | I44: =I24*$C4/$B4 -> 0.61767643 | ... AD44: =AD24*$C4/$B4 -> 0
A45: Ti | B45: =B25*$C5/$B5 -> 0.0035043805 | C45: =C25*$C5/$B5 -> 0.00075093867 | D45: =D25*$C5/$B5 -> 0.0027534418 | E45: =E25*$C5/$B5 -> 0.00087609512 | F45: =F25*$C5/$B5 -> 0.0038798498 | G45: =G25*$C5/$B5 -> 0.0016270338 | H45: =H25*$C5/$B5 -> 0.0013767209 | I45: =I25*$C5/$B5 -> 0.00075093867 | ... AD45: =AD25*$C5/$B5 -> 0
A46: Cr | B46: =B26*$C6/$B6 -> 0 | C46: =C26*$C6/$B6 -> 0.00013158691 | D46: =D26*$C6/$B6 -> 0.00013158691 | E46: =E26*$C6/$B6 -> 0 | F46: =F26*$C6/$B6 -> 0 | G46: =G26*$C6/$B6 -> 0.00013158691 | H46: =H26*$C6/$B6 -> 0 | I46: =I26*$C6/$B6 -> 0 | ... AD46: =AD26*$C6/$B6 -> 0
...

Sheet Biotite
B2: 150 F1000 BIO1 | C2: 151 F1000 BIO2 | D2: 158 F1000 BIO3 | E2: 161 F1000 BIO4 | F2: 13 F1000 BIO5 | G2: 14 F1000 BIO6 | H2: 16 F1000 BIO7 | I2: 13 F1000 BIO5 | J2: 19 F1000 BIO8
A3: SiO2 | B3: 36.379 | C3: 35.989 | D3: 38.087 | E3: 35.965 | F3: 36.547 | G3: 37.956 | H3: 37.315 | I3: 36.547 | J3: 38.304
A4: TiO2 | B4: 7.206 | C4: 6.575 | D4: 7.509 | E4: 8.373 | F4: 6.722 | G4: 6.544 | H4: 6.902 | I4: 6.722 | J4: 7.236
A5: Cr2O3 | B5: 0 | C5: 0 | D5: 0.073 | E5: 0.092 | F5: 0 | G5: 0.077 | H5: 0.051 | I5: 0 | J5: 0.069
A6: Al2O3 | B6: 15.618 | C6: 15.239 | D6: 15.674 | E6: 15.405 | F6: 15.226 | G6: 16.232 | H6: 16.472 | I6: 15.226 | J6: 16.213
A7: FeO | B7: 12.808 | C7: 12.096 | D7: 13.138 | E7: 12.647 | F7: 12.758 | G7: 12.533 | H7: 12.039 | I7: 12.758 | J7: 12.406
A8: MnO | B8: 0.056 | C8: 0.065 | D8: 0 | E8: 0.108 | F8: 0.084 | G8: 0.057 | H8: 0 | I8: 0.084 | J8: 0
A9: NiO | B9: 0.06 | C9: 0 | D9: 0 | E9: 0.057 | F9: 0 | G9: 0 | H9: 0 | I9: 0 | J9: 0
A10: MgO | B10: 12.612 | C10: 12.863 | D10: 12.353 | E10: 11.564 | F10: 12.914 | G10: 12.21 | H10: 12.912 | I10: 12.914 | J10: 12
A11: CaO | B11: 0.247 | C11: 0.157 | D11: 0.716 | E11: 0.514 | F11: 0.412 | G11: 0.451 | H11: 0.335 | I11: 0.412 | J11: 1.135
A12: Na2O | B12: 0.571 | C12: 0.568 | D12: 0.594 | E12: 0.51 | F12: 0.562 | G12: 0.633 | H12: 0.72 | I12: 0.562 | J12: 0.776
A13: K2O | B13: 8.614 | C13: 8.648 | D13: 8.56 | E13: 8.531 | F13: 8.752 | G13: 8.397 | H13: 8.95 | I13: 8.752 | J13: 8.723
A14: H2O | B14: 0 | C14: 0 | D14: 0 | E14: 0 | F14: 0 | G14: 0 | H14: 0 | I14: 0 | J14: 0
... A16: Cl | B16: 0 | C16: 0 | D16: 0 | E16: 0 | F16: 0 | G16: 0 | H16: 0 | I16: 0 | J16: 0
B17: =SUM(B3:B13) -> 94.171 | C17: =SUM(C3:C13) -> 92.2 | D17: =SUM(D3:D13) -> 96.704 | E17: =SUM(E3:E13) -> 93.766 | F17: =SUM(F3:F13) -> 93.977 | G17: =SUM(G3:G13) -> 95.09 | H17: =SUM(H3:H13) -> 95.696 | I17: =SUM(I3:I13) -> 93.977 | J17: =SUM(J3:J13) -> 96.862
